Workbook

Sheet 固定費
B4: 口座引き落とし | C4: 引き落とし日 | D4: 金額 | E4: カード払い | F4: 支払日 | G4: 金額
B5: 家賃 | C5: 毎月27日 | D5: 93000 | E5: 視点・Off Topic（note） | F5: 毎月1日 | G5: 1200
B6: 大学奨学金 | C6: 毎月27日 | D6: 13600 | E6: アイカサ | F6: 毎月1日 | G6: 280
B7: みいちゃんへの返済 | C7: 毎月27日 | D7: 40000 | E7: ディズニープラス | F7: 毎月8日 | G7: 1480
B8: カードローンへの返済 | C8: 毎月27日 | D8: 24000 | E8: postalk | F8: 毎月9日 | G8: 880
B9: ジム代 | C9: 毎月27日 | D9: 8140 | E9: Wi-Fi | F9: 毎月11日 | G9: 6000
E10: Netflix | F10: 毎月16日 | G10: 1490
E11: chapters | F11: 毎月19日 | G11: 2310
E12: コテンラジオ | F12: 毎月20日 | G12: 1100
E13: 電気代 | F13: 毎月20日 | G13: 5000
E14: つみたてNISA | F14: 毎月28日 | G14: 15000
B15: 合計金額 | D15: =SUM(D5:D9) -> 178740 | E15: 合計金額 | G15: =SUM(G5:G14) -> 34740
E17: 毎月固定費合計 | G17: =D15+G15 -> 213480
E18: 給与 | G18: 370000
E19: 残高 | G19: =G18-G17 -> 156520

Sheet 【Monthly】2023年
B1: 合計金額 | C1: 45108 | D1: 45139 | E1: 45170 | F1: 45200 | G1: 45231 | H1: 45261 | I1: 45292
A2: 収入 | B2: =SUM(C2:H2) -> 2253976 | C2: =SUMIFS('フォームの回答 1'!$E:$E,'フォームの回答 1'!$B:$B,">="&C1,'フォームの回答 1'!$H:$H,"収入")-SUMIFS('フォームの回答 1'!$E:$E,'フォームの回答 1'!$B:$B,">"&D1,'フォームの回答 1'!$H:$H,"収入") -> 294581 | D2: =SUMIFS('フォームの回答 1'!$E:$E,'フォームの回答 1'!$B:$B,">="&D1,'フォームの回答 1'!$H:$H,"収入")-SUMIFS('フォームの回答 1'!$E:$E,'フォームの回答 1'!$B:$B,">"&E1,'フォームの回答 1'!$H:$H,"収入") -> 386533 | E2: =SUMIFS('フォームの回答 1'!$E:$E,'フォームの回答 1'!$B:$B,">="&E1,'フォームの回答 1'!$H:$H,"収入")-SUMIFS('フォームの回答 1'!$E:$E,'フォームの回答 1'!$B:$B,">"&F1,'フォームの回答 1'!$H:$H,"収入") -> 467420 | F2: =SUMIFS('フォームの回答 1'!$E:$E,'フォームの回答 1'!$B:$B,">="&F1,'フォームの回答 1'!$H:$H,"収入")-SUMIFS('フォームの回答 1'!$E:$E,'フォームの回答 1'!$B:$B,">"&G1,'フォームの回答 1'!$H:$H,"収入") -> 302210 | G2: =SUMIFS('フォームの回答 1'!$E:$E,'フォームの回答 1'!$B:$B,">="&G1,'フォームの回答 1'!$H:$H,"収入")-SUMIFS('フォームの回答 1'!$E:$E,'フォームの回答 1'!$B:$B,">"&H1,'フォームの回答 1'!$H:$H,"収入") -> 387723 | H2: =SUMIFS('フォームの回答 1'!$E:$E,'フォームの回答 1'!$B:$B,">="&H1,'フォームの回答 1'!$H:$H,"収入")-SUMIFS('フォームの回答 1'!$E:$E,'フォームの回答 1'!$B:$B,">"&I1,'フォームの回答 1'!$H:$H,"収入") -> 415509 | I2: =SUMIFS('フォームの回答 1'!$E:$E,'フォームの回答 1'!$B:$B,">="&I1,'フォームの回答 1'!$H:$H,"収入")-SUMIFS('フォームの回答 1'!$E:$E,'フォームの回答 1'!$B:$B,">"&J1,'フォームの回答 1'!$H:$H,"収入") -> 11887924
A3: 支出 | B3: =SUM(C3:H3) -> 2336539 | C3: =SUMIFS('フォームの回答 1'!$E:$E,'フォームの回答 1'!$B:$B,">="&C1,'フォームの回答 1'!$H:$H,"支出")-SUMIFS('フォームの回答 1'!$E:$E,'フォームの回答 1'!$B:$B,">"&D1,'フォームの回答 1'!$H:$H,"支出") -> 349155 | D3: =SUMIFS('フォームの回答 1'!$E:$E,'フォームの回答 1'!$B:$B,">="&D1,'フォームの回答 1'!$H:$H,"支出")-SUMIFS('フォームの回答 1'!$E:$E,'フォームの回答 1'!$B:$B,">"&E1,'フォームの回答 1'!$H:$H,"支出") -> 393550 | E3: =SUMIFS('フォームの回答 1'!$E:$E,'フォームの回答 1'!$B:$B,">="&E1,'フォームの回答 1'!$H:$H,"支出")-SUMIFS('フォームの回答 1'!$E:$E,'フォームの回答 1'!$B:$B,">"&F1,'フォームの回答 1'!$H:$H,"支出") -> 425591 | F3: =SUMIFS('フォームの回答 1'!$E:$E,'フォームの回答 1'!$B:$B,">="&F1,'フォームの回答 1'!$H:$H,"支出")-SUMIFS('フォームの回答 1'!$E:$E,'フォームの回答 1'!$B:$B,">"&G1,'フォームの回答 1'!$H:$H,"支出") -> 417000 | G3: =SUMIFS('フォームの回答 1'!$E:$E,'フォームの回答 1'!$B:$B,">="&G1,'フォームの回答 1'!$H:$H,"支出")-SUMIFS('フォームの回答 1'!$E:$E,'フォームの回答 1'!$B:$B,">"&H1,'フォームの回答 1'!$H:$H,"支出") -> 321055 | H3: =SUMIFS('フォームの回答 1'!$E:$E,'フォームの回答 1'!$B:$B,">="&H1,'フォームの回答 1'!$H:$H,"支出")-SUMIFS('フォームの回答 1'!$E:$E,'フォームの回答 1'!$B:$B,">"&I1,'フォームの回答 1'!$H:$H,"支出") -> 430188 | I3: =SUMIFS('フォームの回答 1'!$E:$E,'フォームの回答 1'!$B:$B,">="&I1,'フォームの回答 1'!$H:$H,"支出")-SUMIFS('フォームの回答 1'!$E:$E,'フォームの回答 1'!$B:$B,">"&J1,'フォームの回答 1'!$H:$H,"支出") -> 11852954
A4: 差額 | B4: =SUM(C4:H4) -> -82563 | C4: =C2-C3 -> -54574 | D4: =D2-D3 -> -7017 | E4: =E2-E3 -> 41829 | F4: =F2-F3 -> -114790 | G4: =G2-G3 -> 66668 | H4: =H2-H3 -> -14679 | I4: =I2-I3 -> 34970
B5: 内訳
A6: 食費 | B6: =SUM(C6:I6) -> 1353022 | C6: =SUMIFS('フォームの回答 1'!$E:$E,'フォームの回答 1'!$B:$B,">="&C1,'フォームの回答 1'!$H:$H,"支出",'フォームの回答 1'!$D:$D,$A6)-SUMIFS('フォームの回答 1'!$E:$E,'フォームの回答 1'!$B:$B,">"&D1,'フォームの回答 1'!$H:$H,"支出",'フォームの回答 1'!$D:$D,$A6) -> 23773 | D6: =SUMIFS('フォームの回答 1'!$E:$E,'フォームの回答 1'!$B:$B,">="&D1,'フォームの回答 1'!$H:$H,"支出",'フォームの回答 1'!$D:$D,$A6)-SUMIFS('フォームの回答 1'!$E:$E,'フォームの回答 1'!$B:$B,">"&E1,'フォームの回答 1'!$H:$H,"支出",'フォームの回答 1'!$D:$D,$A6) -> 46682 | E6: =SUMIFS('フォームの回答 1'!$E:$E,'フォームの回答 1'!$B:$B,">="&E1,'フォームの回答 1'!$H:$H,"支出",'フォームの回答 1'!$D:$D,$A6)-SUMIFS('フォームの回答 1'!$E:$E,'フォームの回答 1'!$B:$B,">"&F1,'フォームの回答 1'!$H:$H,"支出",'フォームの回答 1'!$D:$D,$A6) -> 71320 | F6: =SUMIFS('フォームの回答 1'!$E:$E,'フォームの回答 1'!$B:$B,">="&F1,'フォームの回答 1'!$H:$H,"支出",'フォームの回答 1'!$D:$D,$A6)-SUMIFS('フォームの回答 1'!$E:$E,'フォームの回答 1'!$B:$B,">"&G1,'フォームの回答 1'!$H:$H,"支出",'フォームの回答 1'!$D:$D,$A6) -> 64549 | G6: =SUMIFS('フォームの回答 1'!$E:$E,'フォームの回答 1'!$B:$B,">="&G1,'フォームの回答 1'!$H:$H,"支出",'フォームの回答 1'!$D:$D,$A6)-SUMIFS('フォームの回答 1'!$E:$E,'フォームの回答 1'!$B:$B,">"&H1,'フォームの回答 1'!$H:$H,"支出",'フォームの回答 1'!$D:$D,$A6) -> 49143 | H6: =SUMIFS('フォームの回答 1'!$E:$E,'フォームの回答 1'!$B:$B,">="&H1,'フォームの回答 1'!$H:$H,"支出",'フォームの回答 1'!$D:$D,$A6)-SUMIFS('フォームの回答 1'!$E:$E,'フォームの回答 1'!$B:$B,">"&I1,'フォームの回答 1'!$H:$H,"支出",'フォームの回答 1'!$D:$D,$A6) -> 43693 | I6: =SUMIFS('フォームの回答 1'!$E:$E,'フォームの回答 1'!$B:$B,">="&I1,'フォームの回答 1'!$H:$H,"支出",'フォームの回答 1'!$D:$D,$A6)-SUMIFS('フォームの回答 1'!$E:$E,'フォームの回答 1'!$B:$B,">"&J1,'フォームの回答 1'!$H:$H,"支出",'フォームの回答 1'!$D:$D,$A6) -> 1053862
A7: 接待交際費 | B7: =SUM(C7:I7) -> 217936 | C7: =SUMIFS('フォームの回答 1'!$E:$E,'フォームの回答 1'!$B:$B,">="&C1,'フォームの回答 1'!$H:$H,"支出",'フォームの回答 1'!$D:$D,$A7)-SUMIFS('フォームの回答 1'!$E:$E,'フォームの回答 1'!$B:$B,">"&D1,'フォームの回答 1'!$H:$H,"支出",'フォームの回答 1'!$D:$D,$A7) -> 10146 | D7: =SUMIFS('フォームの回答 1'!$E:$E,'フォームの回答 1'!$B:$B,">="&D1,'フォームの回答 1'!$H:$H,"支出",'フォームの回答 1'!$D:$D,$A7)-SUMIFS('フォームの回答 1'!$E:$E,'フォームの回答 1'!$B:$B,">"&E1,'フォームの回答 1'!$H:$H,"支出",'フォームの回答 1'!$D:$D,$A7) -> 30222 | E7: =SUMIFS('フォームの回答 1'!$E:$E,'フォームの回答 1'!$B:$B,">="&E1,'フォームの回答 1'!$H:$H,"支出",'フォームの回答 1'!$D:$D,$A7)-SUMIFS('フォームの回答 1'!$E:$E,'フォームの回答 1'!$B:$B,">"&F1,'フォームの回答 1'!$H:$H,"支出",'フォームの回答 1'!$D:$D,$A7) -> 33080 | F7: =SUMIFS('フォームの回答 1'!$E:$E,'フォームの回答 1'!$B:$B,">="&F1,'フォームの回答 1'!$H:$H,"支出",'フォームの回答 1'!$D:$D,$A7)-SUMIFS('フォームの回答 1'!$E:$E,'フォームの回答 1'!$B:$B,">"&G1,'フォームの回答 1'!$H:$H,"支出",'フォームの回答 1'!$D:$D,$A7) -> 35573 | G7: =SUMIFS('フォームの回答 1'!$E:$E,'フォームの回答 1'!$B:$B,">="&G1,'フォームの回答 1'!$H:$H,"支出",'フォームの回答 1'!$D:$D,$A7)-SUMIFS('フォームの回答 1'!$E:$E,'フォームの回答 1'!$B:$B,">"&H1,'フォームの回答 1'!$H:$H,"支出",'フォームの回答 1'!$D:$D,$A7) -> 27715 | H7: =SUMIFS('フォームの回答 1'!$E:$E,'フォームの回答 1'!$B:$B,">="&H1,'フォームの回答 1'!$H:$H,"支出",'フォームの回答 1'!$D:$D,$A7)-SUMIFS('フォームの回答 1'!$E:$E,'フォームの回答 1'!$B:$B,">"&I1,'フォームの回答 1'!$H:$H,"支出",'フォームの回答 1'!$D:$D,$A7) -> 81200 | I7: =SUMIFS('フォームの回答 1'!J:J,'フォームの回答 1'!G:G,">="&I1,'フォームの回答 1'!M:M,"支出",'フォームの回答 1'!I:I,$A7)-SUMIFS('フォームの回答 1'!J:J,'フォームの回答 1'!G:G,">"&J1,'フォームの回答 1'!M:M,"支出",'フォームの回答 1'!I:I,$A7) -> 0
A8: 交通費 | B8: =SUM(C8:I8) -> 1418423 | C8: =SUMIFS('フォームの回答 1'!$E:$E,'フォームの回答 1'!$B:$B,">="&C1,'フォームの回答 1'!$H:$H,"支出",'フォームの回答 1'!$D:$D,$A8)-SUMIFS('フォームの回答 1'!$E:$E,'フォームの回答 1'!$B:$B,">"&D1,'フォームの回答 1'!$H:$H,"支出",'フォームの回答 1'!$D:$D,$A8) -> 10100 | D8: =SUMIFS('フォームの回答 1'!$E:$E,'フォームの回答 1'!$B:$B,">="&D1,'フォームの回答 1'!$H:$H,"支出",'フォームの回答 1'!$D:$D,$A8)-SUMIFS('フォームの回答 1'!$E:$E,'フォームの回答 1'!$B:$B,">"&E1,'フォームの回答 1'!$H:$H,"支出",'フォームの回答 1'!$D:$D,$A8) -> 14505 | E8: =SUMIFS('フォームの回答 1'!$E:$E,'フォームの回答 1'!$B:$B,">="&E1,'フォームの回答 1'!$H:$H,"支出",'フォームの回答 1'!$D:$D,$A8)-SUMIFS('フォームの回答 1'!$E:$E,'フォームの回答 1'!$B:$B,">"&F1,'フォームの回答 1'!$H:$H,"支出",'フォームの回答 1'!$D:$D,$A8) -> 32720 | F8: =SUMIFS('フォームの回答 1'!$E:$E,'フォームの回答 1'!$B:$B,">="&F1,'フォームの回答 1'!$H:$H,"支出",'フォームの回答 1'!$D:$D,$A8)-SUMIFS('フォームの回答 1'!$E:$E,'フォームの回答 1'!$B:$B,">"&G1,'フォームの回答 1'!$H:$H,"支出",'フォームの回答 1'!$D:$D,$A8) -> 86070 | G8: =SUMIFS('フォームの回答 1'!$E:$E,'フォームの回答 1'!$B:$B,">="&G1,'フォームの回答 1'!$H:$H,"支出",'フォームの回答 1'!$D:$D,$A8)-SUMIFS('フォームの回答 1'!$E:$E,'フォームの回答 1'!$B:$B,">"&H1,'フォームの回答 1'!$H:$H,"支出",'フォームの回答 1'!$D:$D,$A8) -> 21010 | H8: =SUMIFS('フォームの回答 1'!$E:$E,'フォームの回答 1'!$B:$B,">="&H1,'フォームの回答 1'!$H:$H,"支出",'フォームの回答 1'!$D:$D,$A8)-SUMIFS('フォームの回答 1'!$E:$E,'フォームの回答 1'!$B:$B,">"&I1,'フォームの回答 1'!$H:$H,"支出",'フォームの回答 1'!$D:$D,$A8) -> 52341 | I8: =SUMIFS('フォームの回答 1'!$E:$E,'フォームの回答 1'!$B:$B,">="&I1,'フォームの回答 1'!$H:$H,"支出",'フォームの回答 1'!$D:$D,$A8)-SUMIFS('フォームの回答 1'!$E:$E,'フォームの回答 1'!$B:$B,">"&J1,'フォームの回答 1'!$H:$H,"支出",'フォームの回答 1'!$D:$D,$A8) -> 1201677
A9: 光熱費 | B9: =SUM(C9:I9) -> 339045 | C9: =SUMIFS('フォームの回答 1'!$E:$E,'フォームの回答 1'!$B:$B,">="&C1,'フォームの回答 1'!$H:$H,"支出",'フォームの回答 1'!$D:$D,$A9)-SUMIFS('フォームの回答 1'!$E:$E,'フォームの回答 1'!$B:$B,">"&D1,'フォームの回答 1'!$H:$H,"支出",'フォームの回答 1'!$D:$D,$A9) -> 2704 | D9: =SUMIFS('フォームの回答 1'!$E:$E,'フォームの回答 1'!$B:$B,">="&D1,'フォームの回答 1'!$H:$H,"支出",'フォームの回答 1'!$D:$D,$A9)-SUMIFS('フォームの回答 1'!$E:$E,'フォームの回答 1'!$B:$B,">"&E1,'フォームの回答 1'!$H:$H,"支出",'フォームの回答 1'!$D:$D,$A9) -> 17837 | E9: =SUMIFS('フォームの回答 1'!$E:$E,'フォームの回答 1'!$B:$B,">="&E1,'フォームの回答 1'!$H:$H,"支出",'フォームの回答 1'!$D:$D,$A9)-SUMIFS('フォームの回答 1'!$E:$E,'フォームの回答 1'!$B:$B,">"&F1,'フォームの回答 1'!$H:$H,"支出",'フォームの回答 1'!$D:$D,$A9) -> 7807 | F9: =SUMIFS('フォームの回答 1'!$E:$E,'フォームの回答 1'!$B:$B,">="&F1,'フォームの回答 1'!$H:$H,"支出",'フォームの回答 1'!$D:$D,$A9)-SUMIFS('フォームの回答 1'!$E:$E,'フォームの回答 1'!$B:$B,">"&G1,'フォームの回答 1'!$H:$H,"支出",'フォームの回答 1'!$D:$D,$A9) -> 7526 | G9: =SUMIFS('フォームの回答 1'!$E:$E,'フォームの回答 1'!$B:$B,">="&G1,'フォームの回答 1'!$H:$H,"支出",'フォームの回答 1'!$D:$D,$A9)-SUMIFS('フォームの回答 1'!$E:$E,'フォームの回答 1'!$B:$B,">"&H1,'フォームの回答 1'!$H:$H,"支出",'フォームの回答 1'!$D:$D,$A9) -> 5318 | H9: =SUMIFS('フォームの回答 1'!$E:$E,'フォームの回答 1'!$B:$B,">="&H1,'フォームの回答 1'!$H:$H,"支出",'フォームの回答 1'!$D:$D,$A9)-SUMIFS('フォームの回答 1'!$E:$E,'フォームの回答 1'!$B:$B,">"&I1,'フォームの回答 1'!$H:$H,"支出",'フォームの回答 1'!$D:$D,$A9) -> 10390 | I9: =SUMIFS('フォームの回答 1'!$E:$E,'フォームの回答 1'!$B:$B,">="&I1,'フォームの回答 1'!$H:$H,"支出",'フォームの回答 1'!$D:$D,$A9)-SUMIFS('フォームの回答 1'!$E:$E,'フォームの回答 1'!$B:$B,">"&J1,'フォームの回答 1'!$H:$H,"支出",'フォームの回答 1'!$D:$D,$A9) -> 287463
A10: スマホ代 | B10: =SUM(C10:I10) -> 211638 | C10: =SUMIFS('フォームの回答 1'!$E:$E,'フォームの回答 1'!$B:$B,">="&C1,'フォームの回答 1'!$H:$H,"支出",'フォームの回答 1'!$D:$D,$A10)-SUMIFS('フォームの回答 1'!$E:$E,'フォームの回答 1'!$B:$B,">"&D1,'フォームの回答 1'!$H:$H,"支出",'フォームの回答 1'!$D:$D,$A10) -> 0 | D10: =SUMIFS('フォームの回答 1'!$E:$E,'フォームの回答 1'!$B:$B,">="&D1,'フォームの回答 1'!$H:$H,"支出",'フォームの回答 1'!$D:$D,$A10)-SUMIFS('フォームの回答 1'!$E:$E,'フォームの回答 1'!$B:$B,">"&E1,'フォームの回答 1'!$H:$H,"支出",'フォームの回答 1'!$D:$D,$A10) -> 14076 | E10: =SUMIFS('フォームの回答 1'!$E:$E,'フォームの回答 1'!$B:$B,">="&E1,'フォームの回答 1'!$H:$H,"支出",'フォームの回答 1'!$D:$D,$A10)-SUMIFS('フォームの回答 1'!$E:$E,'フォームの回答 1'!$B:$B,">"&F1,'フォームの回答 1'!$H:$H,"支出",'フォームの回答 1'!$D:$D,$A10) -> 11710 | F10: =SUMIFS('フォームの回答 1'!$E:$E,'フォームの回答 1'!$B:$B,">="&F1,'フォームの回答 1'!$H:$H,"支出",'フォームの回答 1'!$D:$D,$A10)-SUMIFS('フォームの回答 1'!$E:$E,'フォームの回答 1'!$B:$B,">"&G1,'フォームの回答 1'!$H:$H,"支出",'フォームの回答 1'!$D:$D,$A10) -> 9334 | G10: =SUMIFS('フォームの回答 1'!$E:$E,'フォームの回答 1'!$B:$B,">="&G1,'フォームの回答 1'!$H:$H,"支出",'フォームの回答 1'!$D:$D,$A10)-SUMIFS('フォームの回答 1'!$E:$E,'フォームの回答 1'!$B:$B,">"&H1,'フォームの回答 1'!$H:$H,"支出",'フォームの回答 1'!$D:$D,$A10) -> 6760 | H10: =SUMIFS('フォームの回答 1'!$E:$E,'フォームの回答 1'!$B:$B,">="&H1,'フォームの回答 1'!$H:$H,"支出",'フォームの回答 1'!$D:$D,$A10)-SUMIFS('フォームの回答 1'!$E:$E,'フォームの回答 1'!$B:$B,">"&I1,'フォームの回答 1'!$H:$H,"支出",'フォームの回答 1'!$D:$D,$A10) -> 8363 | I10: =SUMIFS('フォームの回答 1'!$E:$E,'フォームの回答 1'!$B:$B,">="&I1,'フォームの回答 1'!$H:$H,"支出",'フォームの回答 1'!$D:$D,$A10)-SUMIFS('フォームの回答 1'!$E:$E,'フォームの回答 1'!$B:$B,">"&J1,'フォームの回答 1'!$H:$H,"支出",'フォームの回答 1'!$D:$D,$A10) -> 161395
A11: 家賃 | B11: =SUM(C11:I11) -> 3236320 | C11: =SUMIFS('フォームの回答 1'!$E:$E,'フォームの回答 1'!$B:$B,">="&C1,'フォームの回答 1'!$H:$H,"支出",'フォームの回答 1'!$D:$D,$A11)-SUMIFS('フォームの回答 1'!$E:$E,'フォームの回答 1'!$B:$B,">"&D1,'フォームの回答 1'!$H:$H,"支出",'フォームの回答 1'!$D:$D,$A11) -> 35820 | D11: =SUMIFS('フォームの回答 1'!$E:$E,'フォームの回答 1'!$B:$B,">="&D1,'フォームの回答 1'!$H:$H,"支出",'フォームの回答 1'!$D:$D,$A11)-SUMIFS('フォームの回答 1'!$E:$E,'フォームの回答 1'!$B:$B,">"&E1,'フォームの回答 1'!$H:$H,"支出",'フォームの回答 1'!$D:$D,$A11) -> 93000 | E11: =SUMIFS('フォームの回答 1'!$E:$E,'フォームの回答 1'!$B:$B,">="&E1,'フォームの回答 1'!$H:$H,"支出",'フォームの回答 1'!$D:$D,$A11)-SUMIFS('フォームの回答 1'!$E:$E,'フォームの回答 1'!$B:$B,">"&F1,'フォームの回答 1'!$H:$H,"支出",'フォームの回答 1'!$D:$D,$A11) -> 93000 | F11: =SUMIFS('フォームの回答 1'!$E:$E,'フォームの回答 1'!$B:$B,">="&F1,'フォームの回答 1'!$H:$H,"支出",'フォームの回答 1'!$D:$D,$A11)-SUMIFS('フォームの回答 1'!$E:$E,'フォームの回答 1'!$B:$B,">"&G1,'フォームの回答 1'!$H:$H,"支出",'フォームの回答 1'!$D:$D,$A11) -> 93000 | G11: =SUMIFS('フォームの回答 1'!$E:$E,'フォームの回答 1'!$B:$B,">="&G1,'フォームの回答 1'!$H:$H,"支出",'フォームの回答 1'!$D:$D,$A11)-SUMIFS('フォームの回答 1'!$E:$E,'フォームの回答 1'!$B:$B,">"&H1,'フォームの回答 1'!$H:$H,"支出",'フォームの回答 1'!$D:$D,$A11) -> 93000 | H11: =SUMIFS('フォームの回答 1'!$E:$E,'フォームの回答 1'!$B:$B,">="&H1,'フォームの回答 1'!$H:$H,"支出",'フォームの回答 1'!$D:$D,$A11)-SUMIFS('フォームの回答 1'!$E:$E,'フォームの回答 1'!$B:$B,">"&I1,'フォームの回答 1'!$H:$H,"支出",'フォームの回答 1'!$D:$D,$A11) -> 93000 | I11: =SUMIFS('フォームの回答 1'!$E:$E,'フォームの回答 1'!$B:$B,">="&I1,'フォームの回答 1'!$H:$H,"支出",'フォームの回答 1'!$D:$D,$A11)-SUMIFS('フォームの回答 1'!$E:$E,'フォームの回答 1'!$B:$B,">"&J1,'フォームの回答 1'!$H:$H,"支出",'フォームの回答 1'!$D:$D,$A11) -> 2735500
A12: 医療費 | B12: =SUM(C12:I12) -> 65548 | C12: =SUMIFS('フォームの回答 1'!$E:$E,'フォームの回答 1'!$B:$B,">="&C1,'フォームの回答 1'!$H:$H,"支出",'フォームの回答 1'!$D:$D,$A12)-SUMIFS('フォームの回答 1'!$E:$E,'フォームの回答 1'!$B:$B,">"&D1,'フォームの回答 1'!$H:$H,"支出",'フォームの回答 1'!$D:$D,$A12) -> 1980 | D12: =SUMIFS('フォームの回答 1'!$E:$E,'フォームの回答 1'!$B:$B,">="&D1,'フォームの回答 1'!$H:$H,"支出",'フォームの回答 1'!$D:$D,$A12)-SUMIFS('フォームの回答 1'!$E:$E,'フォームの回答 1'!$B:$B,">"&E1,'フォームの回答 1'!$H:$H,"支出",'フォームの回答 1'!$D:$D,$A12) -> 9800 | E12: =SUMIFS('フォームの回答 1'!$E:$E,'フォームの回答 1'!$B:$B,">="&E1,'フォームの回答 1'!$H:$H,"支出",'フォームの回答 1'!$D:$D,$A12)-SUMIFS('フォームの回答 1'!$E:$E,'フォームの回答 1'!$B:$B,">"&F1,'フォームの回答 1'!$H:$H,"支出",'フォームの回答 1'!$D:$D,$A12) -> 3352 | F12: =SUMIFS('フォームの回答 1'!$E:$E,'フォームの回答 1'!$B:$B,">="&F1,'フォームの回答 1'!$H:$H,"支出",'フォームの回答 1'!$D:$D,$A12)-SUMIFS('フォームの回答 1'!$E:$E,'フォームの回答 1'!$B:$B,">"&G1,'フォームの回答 1'!$H:$H,"支出",'フォームの回答 1'!$D:$D,$A12) -> 23463 | G12: =SUMIFS('フォームの回答 1'!$E:$E,'フォームの回答 1'!$B:$B,">="&G1,'フォームの回答 1'!$H:$H,"支出",'フォームの回答 1'!$D:$D,$A12)-SUMIFS('フォームの回答 1'!$E:$E,'フォームの回答 1'!$B:$B,">"&H1,'フォームの回答 1'!$H:$H,"支出",'フォームの回答 1'!$D:$D,$A12) -> 1799 | H12: =SUMIFS('フォームの回答 1'!$E:$E,'フォームの回答 1'!$B:$B,">="&H1,'フォームの回答 1'!$H:$H,"支出",'フォームの回答 1'!$D:$D,$A12)-SUMIFS('フォームの回答 1'!$E:$E,'フォームの回答 1'!$B:$B,">"&I1,'フォームの回答 1'!$H:$H,"支出",'フォームの回答 1'!$D:$D,$A12) -> 1483 | I12: =SUMIFS('フォームの回答 1'!$E:$E,'フォームの回答 1'!$B:$B,">="&I1,'フォームの回答 1'!$H:$H,"支出",'フォームの回答 1'!$D:$D,$A12)-SUMIFS('フォームの回答 1'!$E:$E,'フォームの回答 1'!$B:$B,">"&J1,'フォームの回答 1'!$H:$H,"支出",'フォームの回答 1'!$D:$D,$A12) -> 23671
A13: 服 | B13: =SUM(C13:I13) -> 23110 | C13: =SUMIFS('フォームの回答 1'!$E:$E,'フォームの回答 1'!$B:$B,">="&C1,'フォームの回答 1'!$H:$H,"支出",'フォームの回答 1'!$D:$D,$A13)-SUMIFS('フォームの回答 1'!$E:$E,'フォームの回答 1'!$B:$B,">"&D1,'フォームの回答 1'!$H:$H,"支出",'フォームの回答 1'!$D:$D,$A13) -> 7570 | D13: =SUMIFS('フォームの回答 1'!$E:$E,'フォームの回答 1'!$B:$B,">="&D1,'フォームの回答 1'!$H:$H,"支出",'フォームの回答 1'!$D:$D,$A13)-SUMIFS('フォームの回答 1'!$E:$E,'フォームの回答 1'!$B:$B,">"&E1,'フォームの回答 1'!$H:$H,"支出",'フォームの回答 1'!$D:$D,$A13) -> 3570 | E13: =SUMIFS('フォームの回答 1'!$E:$E,'フォームの回答 1'!$B:$B,">="&E1,'フォームの回答 1'!$H:$H,"支出",'フォームの回答 1'!$D:$D,$A13)-SUMIFS('フォームの回答 1'!$E:$E,'フォームの回答 1'!$B:$B,">"&F1,'フォームの回答 1'!$H:$H,"支出",'フォームの回答 1'!$D:$D,$A13) -> 0 | F13: =SUMIFS('フォームの回答 1'!$E:$E,'フォームの回答 1'!$B:$B,">="&F1,'フォームの回答 1'!$H:$H,"支出",'フォームの回答 1'!$D:$D,$A13)-SUMIFS('フォームの回答 1'!$E:$E,'フォームの回答 1'!$B:$B,">"&G1,'フォームの回答 1'!$H:$H,"支出",'フォームの回答 1'!$D:$D,$A13) -> 1990 | G13: =SUMIFS('フォームの回答 1'!$E:$E,'フォームの回答 1'!$B:$B,">="&G1,'フォームの回答 1'!$H:$H,"支出",'フォームの回答 1'!$D:$D,$A13)-SUMIFS('フォームの回答 1'!$E:$E,'フォームの回答 1'!$B:$B,">"&H1,'フォームの回答 1'!$H:$H,"支出",'フォームの回答 1'!$D:$D,$A13) -> 9980 | H13: =SUMIFS('フォームの回答 1'!$E:$E,'フォームの回答 1'!$B:$B,">="&H1,'フォームの回答 1'!$H:$H,"支出",'フォームの回答 1'!$D:$D,$A13)-SUMIFS('フォームの回答 1'!$E:$E,'フォームの回答 1'!$B:$B,">"&I1,'フォームの回答 1'!$H:$H,"支出",'フォームの回答 1'!$D:$D,$A13) -> 0 | I13: =SUMIFS('フォームの回答 1'!$E:$E,'フォームの回答 1'!$B:$B,">="&I5,'フォームの回答 1'!$H:$H,"支出",'フォームの回答 1'!$D:$D,$A13)-SUMIFS('フォームの回答 1'!$E:$E,'フォームの回答 1'!$B:$B,">"&J5,'フォームの回答 1'!$H:$H,"支出",'フォームの回答 1'!$D:$D,$A13) -> 0
A14: 生活品 | B14: =SUM(C14:I14) -> 1162273 | C14: =SUMIFS('フォームの回答 1'!$E:$E,'フォームの回答 1'!$B:$B,">="&C1,'フォームの回答 1'!$H:$H,"支出",'フォームの回答 1'!$D:$D,$A14)-SUMIFS('フォームの回答 1'!$E:$E,'フォームの回答 1'!$B:$B,">"&D1,'フォームの回答 1'!$H:$H,"支出",'フォームの回答 1'!$D:$D,$A14) -> 41210 | D14: =SUMIFS('フォームの回答 1'!$E:$E,'フォームの回答 1'!$B:$B,">="&D1,'フォームの回答 1'!$H:$H,"支出",'フォームの回答 1'!$D:$D,$A14)-SUMIFS('フォームの回答 1'!$E:$E,'フォームの回答 1'!$B:$B,">"&E1,'フォームの回答 1'!$H:$H,"支出",'フォームの回答 1'!$D:$D,$A14) -> 23760 | E14: =SUMIFS('フォームの回答 1'!$E:$E,'フォームの回答 1'!$B:$B,">="&E1,'フォームの回答 1'!$H:$H,"支出",'フォームの回答 1'!$D:$D,$A14)-SUMIFS('フォームの回答 1'!$E:$E,'フォームの回答 1'!$B:$B,">"&F1,'フォームの回答 1'!$H:$H,"支出",'フォームの回答 1'!$D:$D,$A14) -> 27487 | F14: =SUMIFS('フォームの回答 1'!$E:$E,'フォームの回答 1'!$B:$B,">="&F1,'フォームの回答 1'!$H:$H,"支出",'フォームの回答 1'!$D:$D,$A14)-SUMIFS('フォームの回答 1'!$E:$E,'フォームの回答 1'!$B:$B,">"&G1,'フォームの回答 1'!$H:$H,"支出",'フォームの回答 1'!$D:$D,$A14) -> 15980 | G14: =SUMIFS('フォームの回答 1'!$E:$E,'フォームの回答 1'!$B:$B,">="&G1,'フォームの回答 1'!$H:$H,"支出",'フォームの回答 1'!$D:$D,$A14)-SUMIFS('フォームの回答 1'!$E:$E,'フォームの回答 1'!$B:$B,">"&H1,'フォームの回答 1'!$H:$H,"支出",'フォームの回答 1'!$D:$D,$A14) -> 30350 | H14: =SUMIFS('フォームの回答 1'!$E:$E,'フォームの回答 1'!$B:$B,">="&H1,'フォームの回答 1'!$H:$H,"支出",'フォームの回答 1'!$D:$D,$A14)-SUMIFS('フォームの回答 1'!$E:$E,'フォームの回答 1'!$B:$B,">"&I1,'フォームの回答 1'!$H:$H,"支出",'フォームの回答 1'!$D:$D,$A14) -> 51045 | I14: =SUMIFS('フォームの回答 1'!$E:$E,'フォームの回答 1'!$B:$B,">="&I1,'フォームの回答 1'!$H:$H,"支出",'フォームの回答 1'!$D:$D,$A14)-SUMIFS('フォームの回答 1'!$E:$E,'フォームの回答 1'!$B:$B,">"&J1,'フォームの回答 1'!$H:$H,"支出",'フォームの回答 1'!$D:$D,$A14) -> 972441
A15: 書籍代 | B15: =SUM(C15:I15) -> 247801 | C15: =SUMIFS('フォームの回答 1'!$E:$E,'フォームの回答 1'!$B:$B,">="&C1,'フォームの回答 1'!$H:$H,"支出",'フォームの回答 1'!$D:$D,$A15)-SUMIFS('フォームの回答 1'!$E:$E,'フォームの回答 1'!$B:$B,">"&D1,'フォームの回答 1'!$H:$H,"支出",'フォームの回答 1'!$D:$D,$A15) -> 0 | D15: =SUMIFS('フォームの回答 1'!$E:$E,'フォームの回答 1'!$B:$B,">="&D1,'フォームの回答 1'!$H:$H,"支出",'フォームの回答 1'!$D:$D,$A15)-SUMIFS('フォームの回答 1'!$E:$E,'フォームの回答 1'!$B:$B,">"&E1,'フォームの回答 1'!$H:$H,"支出",'フォームの回答 1'!$D:$D,$A15) -> 8426 | E15: =SUMIFS('フォームの回答 1'!$E:$E,'フォームの回答 1'!$B:$B,">="&E1,'フォームの回答 1'!$H:$H,"支出",'フォームの回答 1'!$D:$D,$A15)-SUMIFS('フォームの回答 1'!$E:$E,'フォームの回答 1'!$B:$B,">"&F1,'フォームの回答 1'!$H:$H,"支出",'フォームの回答 1'!$D:$D,$A15) -> 20215 | F15: =SUMIFS('フォームの回答 1'!$E:$E,'フォームの回答 1'!$B:$B,">="&F1,'フォームの回答 1'!$H:$H,"支出",'フォームの回答 1'!$D:$D,$A15)-SUMIFS('フォームの回答 1'!$E:$E,'フォームの回答 1'!$B:$B,">"&G1,'フォームの回答 1'!$H:$H,"支出",'フォームの回答 1'!$D:$D,$A15) -> 8155 | G15: =SUMIFS('フォームの回答 1'!$E:$E,'フォームの回答 1'!$B:$B,">="&G1,'フォームの回答 1'!$H:$H,"支出",'フォームの回答 1'!$D:$D,$A15)-SUMIFS('フォームの回答 1'!$E:$E,'フォームの回答 1'!$B:$B,">"&H1,'フォームの回答 1'!$H:$H,"支出",'フォームの回答 1'!$D:$D,$A15) -> 4620 | H15: =SUMIFS('フォームの回答 1'!$E:$E,'フォームの回答 1'!$B:$B,">="&H1,'フォームの回答 1'!$H:$H,"支出",'フォームの回答 1'!$D:$D,$A15)-SUMIFS('フォームの回答 1'!$E:$E,'フォームの回答 1'!$B:$B,">"&I1,'フォームの回答 1'!$H:$H,"支出",'フォームの回答 1'!$D:$D,$A15) -> 5663 | I15: =SUMIFS('フォームの回答 1'!$E:$E,'フォームの回答 1'!$B:$B,">="&I1,'フォームの回答 1'!$H:$H,"支出",'フォームの回答 1'!$D:$D,$A15)-SUMIFS('フォームの回答 1'!$E:$E,'フォームの回答 1'!$B:$B,">"&J1,'フォームの回答 1'!$H:$H,"支出",'フォームの回答 1'!$D:$D,$A15) -> 200722
A16: 奨学金・ローン返済 | B16: =SUM(C16:I16) -> 2513229 | C16: =SUMIFS('フォームの回答 1'!$E:$E,'フォームの回答 1'!$B:$B,">="&C1,'フォームの回答 1'!$H:$H,"支出",'フォームの回答 1'!$D:$D,$A16)-SUMIFS('フォームの回答 1'!$E:$E,'フォームの回答 1'!$B:$B,">"&D1,'フォームの回答 1'!$H:$H,"支出",'フォームの回答 1'!$D:$D,$A16) -> 45000 | D16: =SUMIFS('フォームの回答 1'!$E:$E,'フォームの回答 1'!$B:$B,">="&D1,'フォームの回答 1'!$H:$H,"支出",'フォームの回答 1'!$D:$D,$A16)-SUMIFS('フォームの回答 1'!$E:$E,'フォームの回答 1'!$B:$B,">"&E1,'フォームの回答 1'!$H:$H,"支出",'フォームの回答 1'!$D:$D,$A16) -> 31000 | E16: =SUMIFS('フォームの回答 1'!$E:$E,'フォームの回答 1'!$B:$B,">="&E1,'フォームの回答 1'!$H:$H,"支出",'フォームの回答 1'!$D:$D,$A16)-SUMIFS('フォームの回答 1'!$E:$E,'フォームの回答 1'!$B:$B,">"&F1,'フォームの回答 1'!$H:$H,"支出",'フォームの回答 1'!$D:$D,$A16) -> 115940 | F16: =SUMIFS('フォームの回答 1'!$E:$E,'フォームの回答 1'!$B:$B,">="&F1,'フォームの回答 1'!$H:$H,"支出",'フォームの回答 1'!$D:$D,$A16)-SUMIFS('フォームの回答 1'!$E:$E,'フォームの回答 1'!$B:$B,">"&G1,'フォームの回答 1'!$H:$H,"支出",'フォームの回答 1'!$D:$D,$A16) -> 63000 | G16: =SUMIFS('フォームの回答 1'!$E:$E,'フォームの回答 1'!$B:$B,">="&G1,'フォームの回答 1'!$H:$H,"支出",'フォームの回答 1'!$D:$D,$A16)-SUMIFS('フォームの回答 1'!$E:$E,'フォームの回答 1'!$B:$B,">"&H1,'フォームの回答 1'!$H:$H,"支出",'フォームの回答 1'!$D:$D,$A16) -> 63000 | H16: =SUMIFS('フォームの回答 1'!$E:$E,'フォームの回答 1'!$B:$B,">="&H1,'フォームの回答 1'!$H:$H,"支出",'フォームの回答 1'!$D:$D,$A16)-SUMIFS('フォームの回答 1'!$E:$E,'フォームの回答 1'!$B:$B,">"&I1,'フォームの回答 1'!$H:$H,"支出",'フォームの回答 1'!$D:$D,$A16) -> 63000 | I16: =SUMIFS('フォームの回答 1'!$E:$E,'フォームの回答 1'!$B:$B,">="&I1,'フォームの回答 1'!$H:$H,"支出",'フォームの回答 1'!$D:$D,$A16)-SUMIFS('フォームの回答 1'!$E:$E,'フォームの回答 1'!$B:$B,">"&J1,'フォームの回答 1'!$H:$H,"支出",'フォームの回答 1'!$D:$D,$A16) -> 2132289
A17: ツール | B17: =SUM(C17:I17) -> 163847 | C17: =SUMIFS('フォームの回答 1'!$E:$E,'フォームの回答 1'!$B:$B,">="&C1,'フォームの回答 1'!$H:$H,"支出",'フォームの回答 1'!$D:$D,$A17)-SUMIFS('フォームの回答 1'!$E:$E,'フォームの回答 1'!$B:$B,">"&D1,'フォームの回答 1'!$H:$H,"支出",'フォームの回答 1'!$D:$D,$A17) -> 0 | D17: =SUMIFS('フォームの回答 1'!$E:$E,'フォームの回答 1'!$B:$B,">="&D1,'フォームの回答 1'!$H:$H,"支出",'フォームの回答 1'!$D:$D,$A17)-SUMIFS('フォームの回答 1'!$E:$E,'フォームの回答 1'!$B:$B,">"&E1,'フォームの回答 1'!$H:$H,"支出",'フォームの回答 1'!$D:$D,$A17) -> 1480 | E17: =SUMIFS('フォームの回答 1'!$E:$E,'フォームの回答 1'!$B:$B,">="&E1,'フォームの回答 1'!$H:$H,"支出",'フォームの回答 1'!$D:$D,$A17)-SUMIFS('フォームの回答 1'!$E:$E,'フォームの回答 1'!$B:$B,">"&F1,'フォームの回答 1'!$H:$H,"支出",'フォームの回答 1'!$D:$D,$A17) -> 1480 | F17: =SUMIFS('フォームの回答 1'!$E:$E,'フォームの回答 1'!$B:$B,">="&F1,'フォームの回答 1'!$H:$H,"支出",'フォームの回答 1'!$D:$D,$A17)-SUMIFS('フォームの回答 1'!$E:$E,'フォームの回答 1'!$B:$B,">"&G1,'フォームの回答 1'!$H:$H,"支出",'フォームの回答 1'!$D:$D,$A17) -> 880 | G17: =SUMIFS('フォームの回答 1'!$E:$E,'フォームの回答 1'!$B:$B,">="&G1,'フォームの回答 1'!$H:$H,"支出",'フォームの回答 1'!$D:$D,$A17)-SUMIFS('フォームの回答 1'!$E:$E,'フォームの回答 1'!$B:$B,">"&H1,'フォームの回答 1'!$H:$H,"支出",'フォームの回答 1'!$D:$D,$A17) -> 880 | H17: =SUMIFS('フォームの回答 1'!$E:$E,'フォームの回答 1'!$B:$B,">="&H1,'フォームの回答 1'!$H:$H,"支出",'フォームの回答 1'!$D:$D,$A17)-SUMIFS('フォームの回答 1'!$E:$E,'フォームの回答 1'!$B:$B,">"&I1,'フォームの回答 1'!$H:$H,"支出",'フォームの回答 1'!$D:$D,$A17) -> 880 | I17: =SUMIFS('フォームの回答 1'!$E:$E,'フォームの回答 1'!$B:$B,">="&I1,'フォームの回答 1'!$H:$H,"支出",'フォームの回答 1'!$D:$D,$A17)-SUMIFS('フォームの回答 1'!$E:$E,'フォームの回答 1'!$B:$B,">"&J1,'フォームの回答 1'!$H:$H,"支出",'フォームの回答 1'!$D:$D,$A17) -> 158247
A18: 勉強費 | B18: =SUM(C18:I18) -> 254338 | C18: =SUMIFS('フォームの回答 1'!$E:$E,'フォームの回答 1'!$B:$B,">="&C1,'フォームの回答 1'!$H:$H,"支出",'フォームの回答 1'!$D:$D,$A18)-SUMIFS('フォームの回答 1'!$E:$E,'フォームの回答 1'!$B:$B,">"&D1,'フォームの回答 1'!$H:$H,"支出",'フォームの回答 1'!$D:$D,$A18) -> 6780 | D18: =SUMIFS('フォームの回答 1'!$E:$E,'フォームの回答 1'!$B:$B,">="&D1,'フォームの回答 1'!$H:$H,"支出",'フォームの回答 1'!$D:$D,$A18)-SUMIFS('フォームの回答 1'!$E:$E,'フォームの回答 1'!$B:$B,">"&E1,'フォームの回答 1'!$H:$H,"支出",'フォームの回答 1'!$D:$D,$A18) -> 7480 | E18: =SUMIFS('フォームの回答 1'!$E:$E,'フォームの回答 1'!$B:$B,">="&E1,'フォームの回答 1'!$H:$H,"支出",'フォームの回答 1'!$D:$D,$A18)-SUMIFS('フォームの回答 1'!$E:$E,'フォームの回答 1'!$B:$B,">"&F1,'フォームの回答 1'!$H:$H,"支出",'フォームの回答 1'!$D:$D,$A18) -> 7480 | F18: =SUMIFS('フォームの回答 1'!$E:$E,'フォームの回答 1'!$B:$B,">="&F1,'フォームの回答 1'!$H:$H,"支出",'フォームの回答 1'!$D:$D,$A18)-SUMIFS('フォームの回答 1'!$E:$E,'フォームの回答 1'!$B:$B,">"&G1,'フォームの回答 1'!$H:$H,"支出",'フォームの回答 1'!$D:$D,$A18) -> 7480 | G18: =SUMIFS('フォームの回答 1'!$E:$E,'フォームの回答 1'!$B:$B,">="&G1,'フォームの回答 1'!$H:$H,"支出",'フォームの回答 1'!$D:$D,$A18)-SUMIFS('フォームの回答 1'!$E:$E,'フォームの回答 1'!$B:$B,">"&H1,'フォームの回答 1'!$H:$H,"支出",'フォームの回答 1'!$D:$D,$A18) -> 7480 | H18: =SUMIFS('フォームの回答 1'!$E:$E,'フォームの回答 1'!$B:$B,">="&H1,'フォームの回答 1'!$H:$H,"支出",'フォームの回答 1'!$D:$D,$A18)-SUMIFS('フォームの回答 1'!$E:$E,'フォームの回答 1'!$B:$B,">"&I1,'フォームの回答 1'!$H:$H,"支出",'フォームの回答 1'!$D:$D,$A18) -> 7480 | I18: =SUMIFS('フォームの回答 1'!$E:$E,'フォームの回答 1'!$B:$B,">="&I1,'フォームの回答 1'!$H:$H,"支出",'フォームの回答 1'!$D:$D,$A18)-SUMIFS('フォームの回答 1'!$E:$E,'フォームの回答 1'!$B:$B,">"&J1,'フォームの回答 1'!$H:$H,"支出",'フォームの回答 1'!$D:$D,$A18) -> 210158
A19: クレジット引き落とし | C19: =SUMIFS('フォームの回答 1'!$E:$E,'フォームの回答 1'!$B:$B,">="&C1,'フォームの回答 1'!$H:$H,"支出",'フォームの回答 1'!$D:$D,$A19)-SUMIFS('フォームの回答 1'!$E:$E,'フォームの回答 1'!$B:$B,">"&D1,'フォームの回答 1'!$H:$H,"支出",'フォームの回答 1'!$D:$D,$A19) -> 156972

Sheet 【Monthly】2024年
B1: 合計金額 | C1: 45292 | D1: 45323 | E1: 45352 | F1: 45383 | G1: 45413 | H1: 45444 | I1: 45474 | J1: 45505 | K1: 45536 | L1: 45566 | M1: 45597 | N1: 45627 | O1: 平均
A2: 収入 | B2: =SUM(C2:H2) -> 2583909 | C2: =SUMIFS('フォームの回答 1'!$E:$E,'フォームの回答 1'!$B:$B,">="&C1,'フォームの回答 1'!$H:$H,"収入")-SUMIFS('フォームの回答 1'!$E:$E,'フォームの回答 1'!$B:$B,">"&D1,'フォームの回答 1'!$H:$H,"収入") -> 492780 | D2: =SUMIFS('フォームの回答 1'!$E:$E,'フォームの回答 1'!$B:$B,">="&D1,'フォームの回答 1'!$H:$H,"収入")-SUMIFS('フォームの回答 1'!$E:$E,'フォームの回答 1'!$B:$B,">"&E1,'フォームの回答 1'!$H:$H,"収入") -> 455893 | E2: =SUMIFS('フォームの回答 1'!$E:$E,'フォームの回答 1'!$B:$B,">="&E1,'フォームの回答 1'!$H:$H,"収入")-SUMIFS('フォームの回答 1'!$E:$E,'フォームの回答 1'!$B:$B,">"&F1,'フォームの回答 1'!$H:$H,"収入") -> 443820 | F2: =SUMIFS('フォームの回答 1'!$E:$E,'フォームの回答 1'!$B:$B,">="&F1,'フォームの回答 1'!$H:$H,"収入")-SUMIFS('フォームの回答 1'!$E:$E,'フォームの回答 1'!$B:$B,">"&G1,'フォームの回答 1'!$H:$H,"収入") -> 367168 | G2: =SUMIFS('フォームの回答 1'!$E:$E,'フォームの回答 1'!$B:$B,">="&G1,'フォームの回答 1'!$H:$H,"収入")-SUMIFS('フォームの回答 1'!$E:$E,'フォームの回答 1'!$B:$B,">"&H1,'フォームの回答 1'!$H:$H,"収入") -> 401043 | H2: =SUMIFS('フォームの回答 1'!$E:$E,'フォームの回答 1'!$B:$B,">="&H1,'フォームの回答 1'!$H:$H,"収入")-SUMIFS('フォームの回答 1'!$E:$E,'フォームの回答 1'!$B:$B,">"&I1,'フォームの回答 1'!$H:$H,"収入") -> 423205 | I2: =SUMIFS('フォームの回答 1'!$E:$E,'フォームの回答 1'!$B:$B,">="&I1,'フォームの回答 1'!$H:$H,"収入")-SUMIFS('フォームの回答 1'!$E:$E,'フォームの回答 1'!$B:$B,">"&J1,'フォームの回答 1'!$H:$H,"収入") -> 384500 | J2: =SUMIFS('フォームの回答 1'!$E:$E,'フォームの回答 1'!$B:$B,">="&J1,'フォームの回答 1'!$H:$H,"収入")-SUMIFS('フォームの回答 1'!$E:$E,'フォームの回答 1'!$B:$B,">"&K1,'フォームの回答 1'!$H:$H,"収入") -> 362802 | ... N2: =SUMIFS('フォームの回答 1'!$E:$E,'フォームの回答 1'!$B:$B,">="&N1,'フォームの回答 1'!$H:$H,"収入")-SUMIFS('フォームの回答 1'!$E:$E,'フォームの回答 1'!$B:$B,">"&O1,'フォームの回答 1'!$H:$H,"収入") -> 7428937
A3: 支出 | B3: =SUM(C3:H3) -> 2506457 | C3: =SUMIFS('フォームの回答 1'!$E:$E,'フォームの回答 1'!$B:$B,">="&C1,'フォームの回答 1'!$H:$H,"支出")-SUMIFS('フォームの回答 1'!$E:$E,'フォームの回答 1'!$B:$B,">"&D1,'フォームの回答 1'!$H:$H,"支出") -> 516953 | D3: =SUMIFS('フォームの回答 1'!$E:$E,'フォームの回答 1'!$B:$B,">="&D1,'フォームの回答 1'!$H:$H,"支出")-SUMIFS('フォームの回答 1'!$E:$E,'フォームの回答 1'!$B:$B,">"&E1,'フォームの回答 1'!$H:$H,"支出") -> 377067 | E3: =SUMIFS('フォームの回答 1'!$E:$E,'フォームの回答 1'!$B:$B,">="&E1,'フォームの回答 1'!$H:$H,"支出")-SUMIFS('フォームの回答 1'!$E:$E,'フォームの回答 1'!$B:$B,">"&F1,'フォームの回答 1'!$H:$H,"支出") -> 422067 | F3: =SUMIFS('フォームの回答 1'!$E:$E,'フォームの回答 1'!$B:$B,">="&F1,'フォームの回答 1'!$H:$H,"支出")-SUMIFS('フォームの回答 1'!$E:$E,'フォームの回答 1'!$B:$B,">"&G1,'フォームの回答 1'!$H:$H,"支出") -> 363280 | G3: =SUMIFS('フォームの回答 1'!$E:$E,'フォームの回答 1'!$B:$B,">="&G1,'フォームの回答 1'!$H:$H,"支出")-SUMIFS('フォームの回答 1'!$E:$E,'フォームの回答 1'!$B:$B,">"&H1,'フォームの回答 1'!$H:$H,"支出") -> 442981 | H3: =SUMIFS('フォームの回答 1'!$E:$E,'フォームの回答 1'!$B:$B,">="&H1,'フォームの回答 1'!$H:$H,"支出")-SUMIFS('フォームの回答 1'!$E:$E,'フォームの回答 1'!$B:$B,">"&I1,'フォームの回答 1'!$H:$H,"支出") -> 384109 | I3: =SUMIFS('フォームの回答 1'!$E:$E,'フォームの回答 1'!$B:$B,">="&I1,'フォームの回答 1'!$H:$H,"支出")-SUMIFS('フォームの回答 1'!$E:$E,'フォームの回答 1'!$B:$B,">"&J1,'フォームの回答 1'!$H:$H,"支出") -> 352913 | J3: =SUMIFS('フォームの回答 1'!$E:$E,'フォームの回答 1'!$B:$B,">="&J1,'フォームの回答 1'!$H:$H,"支出")-SUMIFS('フォームの回答 1'!$E:$E,'フォームの回答 1'!$B:$B,">"&K1,'フォームの回答 1'!$H:$H,"支出") -> 354855 | ... N3: =SUMIFS('フォームの回答 1'!$E:$E,'フォームの回答 1'!$B:$B,">="&N1,'フォームの回答 1'!$H:$H,"支出")-SUMIFS('フォームの回答 1'!$E:$E,'フォームの回答 1'!$B:$B,">"&O1,'フォームの回答 1'!$H:$H,"支出") -> 7556293
A4: 差額 | B4: =SUM(C4:H4) -> 77452 | C4: =C2-C3 -> -24173 | D4: =D2-D3 -> 78826 | E4: =E2-E3 -> 21753 | F4: =F2-F3 -> 3888 | G4: =G2-G3 -> -41938 | H4: =H2-H3 -> 39096 | I4: =I2-I3 -> 31587 | J4: =J2-J3 -> 7947 | ... N4: =N2-N3 -> -127356
B5: 内訳
A6: 食費 | B6: =SUM(C6:N6) -> 1065817 | C6: =SUMIFS('フォームの回答 1'!$E:$E,'フォームの回答 1'!$B:$B,">="&C1,'フォームの回答 1'!$H:$H,"支出",'フォームの回答 1'!$D:$D,$A6)-SUMIFS('フォームの回答 1'!$E:$E,'フォームの回答 1'!$B:$B,">"&D1,'フォームの回答 1'!$H:$H,"支出",'フォームの回答 1'!$D:$D,$A6) -> 34762 | D6: =SUMIFS('フォームの回答 1'!$E:$E,'フォームの回答 1'!$B:$B,">="&D1,'フォームの回答 1'!$H:$H,"支出",'フォームの回答 1'!$D:$D,$A6)-SUMIFS('フォームの回答 1'!$E:$E,'フォームの回答 1'!$B:$B,">"&E1,'フォームの回答 1'!$H:$H,"支出",'フォームの回答 1'!$D:$D,$A6) -> 41876 | E6: =SUMIFS('フォームの回答 1'!$E:$E,'フォームの回答 1'!$B:$B,">="&E1,'フォームの回答 1'!$H:$H,"支出",'フォームの回答 1'!$D:$D,$A6)-SUMIFS('フォームの回答 1'!$E:$E,'フォームの回答 1'!$B:$B,">"&F1,'フォームの回答 1'!$H:$H,"支出",'フォームの回答 1'!$D:$D,$A6) -> 40602 | F6: =SUMIFS('フォームの回答 1'!$E:$E,'フォームの回答 1'!$B:$B,">="&F1,'フォームの回答 1'!$H:$H,"支出",'フォームの回答 1'!$D:$D,$A6)-SUMIFS('フォームの回答 1'!$E:$E,'フォームの回答 1'!$B:$B,">"&G1,'フォームの回答 1'!$H:$H,"支出",'フォームの回答 1'!$D:$D,$A6) -> 35895 | G6: =SUMIFS('フォームの回答 1'!$E:$E,'フォームの回答 1'!$B:$B,">="&G1,'フォームの回答 1'!$H:$H,"支出",'フォームの回答 1'!$D:$D,$A6)-SUMIFS('フォームの回答 1'!$E:$E,'フォームの回答 1'!$B:$B,">"&H1,'フォームの回答 1'!$H:$H,"支出",'フォームの回答 1'!$D:$D,$A6) -> 42918 | H6: =SUMIFS('フォームの回答 1'!$E:$E,'フォームの回答 1'!$B:$B,">="&H1,'フォームの回答 1'!$H:$H,"支出",'フォームの回答 1'!$D:$D,$A6)-SUMIFS('フォームの回答 1'!$E:$E,'フォームの回答 1'!$B:$B,">"&I1,'フォームの回答 1'!$H:$H,"支出",'フォームの回答 1'!$D:$D,$A6) -> 33681 | I6: =SUMIFS('フォームの回答 1'!$E:$E,'フォームの回答 1'!$B:$B,">="&I1,'フォームの回答 1'!$H:$H,"支出",'フォームの回答 1'!$D:$D,$A6)-SUMIFS('フォームの回答 1'!$E:$E,'フォームの回答 1'!$B:$B,">"&J1,'フォームの回答 1'!$H:$H,"支出",'フォームの回答 1'!$D:$D,$A6) -> 31926 | J6: =SUMIFS('フォームの回答 1'!$E:$E,'フォームの回答 1'!$B:$B,">="&J1,'フォームの回答 1'!$H:$H,"支出",'フォームの回答 1'!$D:$D,$A6)-SUMIFS('フォームの回答 1'!$E:$E,'フォームの回答 1'!$B:$B,">"&K1,'フォームの回答 1'!$H:$H,"支出",'フォームの回答 1'!$D:$D,$A6) -> 31370 | ... N6: =SUMIFS('フォームの回答 1'!$E:$E,'フォームの回答 1'!$B:$B,">="&N1,'フォームの回答 1'!$H:$H,"支出",'フォームの回答 1'!$D:$D,$A6)-SUMIFS('フォームの回答 1'!$E:$E,'フォームの回答 1'!$B:$B,">"&O1,'フォームの回答 1'!$H:$H,"支出",'フォームの回答 1'!$D:$D,$A6) -> 656871 | O6: =B6/12 -> 88818.083 | Q6: =O6+O10+O14+O18+O17+O15 -> 235202.92
A7: 接待交際費 | B7: =SUM(C7:N7) -> 1927983 | C7: =SUMIFS('フォームの回答 1'!$E:$E,'フォームの回答 1'!$B:$B,">="&C1,'フォームの回答 1'!$H:$H,"支出",'フォームの回答 1'!$D:$D,$A7)-SUMIFS('フォームの回答 1'!$E:$E,'フォームの回答 1'!$B:$B,">"&D1,'フォームの回答 1'!$H:$H,"支出",'フォームの回答 1'!$D:$D,$A7) -> 118008 | D7: =SUMIFS('フォームの回答 1'!$E:$E,'フォームの回答 1'!$B:$B,">="&D1,'フォームの回答 1'!$H:$H,"支出",'フォームの回答 1'!$D:$D,$A7)-SUMIFS('フォームの回答 1'!$E:$E,'フォームの回答 1'!$B:$B,">"&E1,'フォームの回答 1'!$H:$H,"支出",'フォームの回答 1'!$D:$D,$A7) -> 39655 | E7: =SUMIFS('フォームの回答 1'!$E:$E,'フォームの回答 1'!$B:$B,">="&E1,'フォームの回答 1'!$H:$H,"支出",'フォームの回答 1'!$D:$D,$A7)-SUMIFS('フォームの回答 1'!$E:$E,'フォームの回答 1'!$B:$B,">"&F1,'フォームの回答 1'!$H:$H,"支出",'フォームの回答 1'!$D:$D,$A7) -> 92774 | F7: =SUMIFS('フォームの回答 1'!$E:$E,'フォームの回答 1'!$B:$B,">="&F1,'フォームの回答 1'!$H:$H,"支出",'フォームの回答 1'!$D:$D,$A7)-SUMIFS('フォームの回答 1'!$E:$E,'フォームの回答 1'!$B:$B,">"&G1,'フォームの回答 1'!$H:$H,"支出",'フォームの回答 1'!$D:$D,$A7) -> 66942 | G7: =SUMIFS('フォームの回答 1'!$E:$E,'フォームの回答 1'!$B:$B,">="&G1,'フォームの回答 1'!$H:$H,"支出",'フォームの回答 1'!$D:$D,$A7)-SUMIFS('フォームの回答 1'!$E:$E,'フォームの回答 1'!$B:$B,">"&H1,'フォームの回答 1'!$H:$H,"支出",'フォームの回答 1'!$D:$D,$A7) -> 59566 | H7: =SUMIFS('フォームの回答 1'!$E:$E,'フォームの回答 1'!$B:$B,">="&H1,'フォームの回答 1'!$H:$H,"支出",'フォームの回答 1'!$D:$D,$A7)-SUMIFS('フォームの回答 1'!$E:$E,'フォームの回答 1'!$B:$B,">"&I1,'フォームの回答 1'!$H:$H,"支出",'フォームの回答 1'!$D:$D,$A7) -> 73222 | I7: =SUMIFS('フォームの回答 1'!$E:$E,'フォームの回答 1'!$B:$B,">="&I1,'フォームの回答 1'!$H:$H,"支出",'フォームの回答 1'!$D:$D,$A7)-SUMIFS('フォームの回答 1'!$E:$E,'フォームの回答 1'!$B:$B,">"&J1,'フォームの回答 1'!$H:$H,"支出",'フォームの回答 1'!$D:$D,$A7) -> 56489 | J7: =SUMIFS('フォームの回答 1'!$E:$E,'フォームの回答 1'!$B:$B,">="&J1,'フォームの回答 1'!$H:$H,"支出",'フォームの回答 1'!$D:$D,$A7)-SUMIFS('フォームの回答 1'!$E:$E,'フォームの回答 1'!$B:$B,">"&K1,'フォームの回答 1'!$H:$H,"支出",'フォームの回答 1'!$D:$D,$A7) -> 46220 | ... N7: =SUMIFS('フォームの回答 1'!$E:$E,'フォームの回答 1'!$B:$B,">="&N1,'フォームの回答 1'!$H:$H,"支出",'フォームの回答 1'!$D:$D,$A7)-SUMIFS('フォームの回答 1'!$E:$E,'フォームの回答 1'!$B:$B,">"&O1,'フォームの回答 1'!$H:$H,"支出",'フォームの回答 1'!$D:$D,$A7) -> 1197655 | O7: =B7/12 -> 160665.25
A8: 交通費 | B8: =SUM(C8:N8) -> 1220607 | C8: =SUMIFS('フォームの回答 1'!$E:$E,'フォームの回答 1'!$B:$B,">="&C1,'フォームの回答 1'!$H:$H,"支出",'フォームの回答 1'!$D:$D,$A8)-SUMIFS('フォームの回答 1'!$E:$E,'フォームの回答 1'!$B:$B,">"&D1,'フォームの回答 1'!$H:$H,"支出",'フォームの回答 1'!$D:$D,$A8) -> 27960 | D8: =SUMIFS('フォームの回答 1'!$E:$E,'フォームの回答 1'!$B:$B,">="&D1,'フォームの回答 1'!$H:$H,"支出",'フォームの回答 1'!$D:$D,$A8)-SUMIFS('フォームの回答 1'!$E:$E,'フォームの回答 1'!$B:$B,">"&E1,'フォームの回答 1'!$H:$H,"支出",'フォームの回答 1'!$D:$D,$A8) -> 67770 | E8: =SUMIFS('フォームの回答 1'!$E:$E,'フォームの回答 1'!$B:$B,">="&E1,'フォームの回答 1'!$H:$H,"支出",'フォームの回答 1'!$D:$D,$A8)-SUMIFS('フォームの回答 1'!$E:$E,'フォームの回答 1'!$B:$B,">"&F1,'フォームの回答 1'!$H:$H,"支出",'フォームの回答 1'!$D:$D,$A8) -> 19010 | F8: =SUMIFS('フォームの回答 1'!$E:$E,'フォームの回答 1'!$B:$B,">="&F1,'フォームの回答 1'!$H:$H,"支出",'フォームの回答 1'!$D:$D,$A8)-SUMIFS('フォームの回答 1'!$E:$E,'フォームの回答 1'!$B:$B,">"&G1,'フォームの回答 1'!$H:$H,"支出",'フォームの回答 1'!$D:$D,$A8) -> 7600 | G8: =SUMIFS('フォームの回答 1'!$E:$E,'フォームの回答 1'!$B:$B,">="&G1,'フォームの回答 1'!$H:$H,"支出",'フォームの回答 1'!$D:$D,$A8)-SUMIFS('フォームの回答 1'!$E:$E,'フォームの回答 1'!$B:$B,">"&H1,'フォームの回答 1'!$H:$H,"支出",'フォームの回答 1'!$D:$D,$A8) -> 52480 | H8: =SUMIFS('フォームの回答 1'!$E:$E,'フォームの回答 1'!$B:$B,">="&H1,'フォームの回答 1'!$H:$H,"支出",'フォームの回答 1'!$D:$D,$A8)-SUMIFS('フォームの回答 1'!$E:$E,'フォームの回答 1'!$B:$B,">"&I1,'フォームの回答 1'!$H:$H,"支出",'フォームの回答 1'!$D:$D,$A8) -> 33140 | I8: =SUMIFS('フォームの回答 1'!$E:$E,'フォームの回答 1'!$B:$B,">="&I1,'フォームの回答 1'!$H:$H,"支出",'フォームの回答 1'!$D:$D,$A8)-SUMIFS('フォームの回答 1'!$E:$E,'フォームの回答 1'!$B:$B,">"&J1,'フォームの回答 1'!$H:$H,"支出",'フォームの回答 1'!$D:$D,$A8) -> 20500 | J8: =SUMIFS('フォームの回答 1'!$E:$E,'フォームの回答 1'!$B:$B,">="&J1,'フォームの回答 1'!$H:$H,"支出",'フォームの回答 1'!$D:$D,$A8)-SUMIFS('フォームの回答 1'!$E:$E,'フォームの回答 1'!$B:$B,">"&K1,'フォームの回答 1'!$H:$H,"支出",'フォームの回答 1'!$D:$D,$A8) -> 45680 | ... N8: =SUMIFS('フォームの回答 1'!$E:$E,'フォームの回答 1'!$B:$B,">="&N1,'フォームの回答 1'!$H:$H,"支出",'フォームの回答 1'!$D:$D,$A8)-SUMIFS('フォームの回答 1'!$E:$E,'フォームの回答 1'!$B:$B,">"&O1,'フォームの回答 1'!$H:$H,"支出",'フォームの回答 1'!$D:$D,$A8) -> 811163 | O8: =B8/12 -> 101717.25
A9: 光熱費 | B9: =SUM(C9:N9) -> 287463 | C9: =SUMIFS('フォームの回答 1'!$E:$E,'フォームの回答 1'!$B:$B,">="&C1,'フォームの回答 1'!$H:$H,"支出",'フォームの回答 1'!$D:$D,$A9)-SUMIFS('フォームの回答 1'!$E:$E,'フォームの回答 1'!$B:$B,">"&D1,'フォームの回答 1'!$H:$H,"支出",'フォームの回答 1'!$D:$D,$A9) -> 10991 | D9: =SUMIFS('フォームの回答 1'!$E:$E,'フォームの回答 1'!$B:$B,">="&D1,'フォームの回答 1'!$H:$H,"支出",'フォームの回答 1'!$D:$D,$A9)-SUMIFS('フォームの回答 1'!$E:$E,'フォームの回答 1'!$B:$B,">"&E1,'フォームの回答 1'!$H:$H,"支出",'フォームの回答 1'!$D:$D,$A9) -> 8466 | E9: =SUMIFS('フォームの回答 1'!$E:$E,'フォームの回答 1'!$B:$B,">="&E1,'フォームの回答 1'!$H:$H,"支出",'フォームの回答 1'!$D:$D,$A9)-SUMIFS('フォームの回答 1'!$E:$E,'フォームの回答 1'!$B:$B,">"&F1,'フォームの回答 1'!$H:$H,"支出",'フォームの回答 1'!$D:$D,$A9) -> 5318 | F9: =SUMIFS('フォームの回答 1'!$E:$E,'フォームの回答 1'!$B:$B,">="&F1,'フォームの回答 1'!$H:$H,"支出",'フォームの回答 1'!$D:$D,$A9)-SUMIFS('フォームの回答 1'!$E:$E,'フォームの回答 1'!$B:$B,">"&G1,'フォームの回答 1'!$H:$H,"支出",'フォームの回答 1'!$D:$D,$A9) -> 8490 | G9: =SUMIFS('フォームの回答 1'!$E:$E,'フォームの回答 1'!$B:$B,">="&G1,'フォームの回答 1'!$H:$H,"支出",'フォームの回答 1'!$D:$D,$A9)-SUMIFS('フォームの回答 1'!$E:$E,'フォームの回答 1'!$B:$B,">"&H1,'フォームの回答 1'!$H:$H,"支出",'フォームの回答 1'!$D:$D,$A9) -> 5318 | H9: =SUMIFS('フォームの回答 1'!$E:$E,'フォームの回答 1'!$B:$B,">="&H1,'フォームの回答 1'!$H:$H,"支出",'フォームの回答 1'!$D:$D,$A9)-SUMIFS('フォームの回答 1'!$E:$E,'フォームの回答 1'!$B:$B,">"&I1,'フォームの回答 1'!$H:$H,"支出",'フォームの回答 1'!$D:$D,$A9) -> 8514 | I9: =SUMIFS('フォームの回答 1'!$E:$E,'フォームの回答 1'!$B:$B,">="&I1,'フォームの回答 1'!$H:$H,"支出",'フォームの回答 1'!$D:$D,$A9)-SUMIFS('フォームの回答 1'!$E:$E,'フォームの回答 1'!$B:$B,">"&J1,'フォームの回答 1'!$H:$H,"支出",'フォームの回答 1'!$D:$D,$A9) -> 5318 | J9: =SUMIFS('フォームの回答 1'!$E:$E,'フォームの回答 1'!$B:$B,">="&J1,'フォームの回答 1'!$H:$H,"支出",'フォームの回答 1'!$D:$D,$A9)-SUMIFS('フォームの回答 1'!$E:$E,'フォームの回答 1'!$B:$B,">"&K1,'フォームの回答 1'!$H:$H,"支出",'フォームの回答 1'!$D:$D,$A9) -> 8490 | ... N9: =SUMIFS('フォームの回答 1'!$E:$E,'フォームの回答 1'!$B:$B,">="&N1,'フォームの回答 1'!$H:$H,"支出",'フォームの回答 1'!$D:$D,$A9)-SUMIFS('フォームの回答 1'!$E:$E,'フォームの回答 1'!$B:$B,">"&O1,'フォームの回答 1'!$H:$H,"支出",'フォームの回答 1'!$D:$D,$A9) -> 206235 | O9: =B9/12 -> 23955.25
A10: スマホ代 | B10: =SUM(C10:N10) -> 164365 | C10: =SUMIFS('フォームの回答 1'!$E:$E,'フォームの回答 1'!$B:$B,">="&C1,'フォームの回答 1'!$H:$H,"支出",'フォームの回答 1'!$D:$D,$A10)-SUMIFS('フォームの回答 1'!$E:$E,'フォームの回答 1'!$B:$B,">"&D1,'フォームの回答 1'!$H:$H,"支出",'フォームの回答 1'!$D:$D,$A10) -> 5492 | D10: =SUMIFS('フォームの回答 1'!$E:$E,'フォームの回答 1'!$B:$B,">="&D1,'フォームの回答 1'!$H:$H,"支出",'フォームの回答 1'!$D:$D,$A10)-SUMIFS('フォームの回答 1'!$E:$E,'フォームの回答 1'!$B:$B,">"&E1,'フォームの回答 1'!$H:$H,"支出",'フォームの回答 1'!$D:$D,$A10) -> 4810 | E10: =SUMIFS('フォームの回答 1'!$E:$E,'フォームの回答 1'!$B:$B,">="&E1,'フォームの回答 1'!$H:$H,"支出",'フォームの回答 1'!$D:$D,$A10)-SUMIFS('フォームの回答 1'!$E:$E,'フォームの回答 1'!$B:$B,">"&F1,'フォームの回答 1'!$H:$H,"支出",'フォームの回答 1'!$D:$D,$A10) -> 5780 | F10: =SUMIFS('フォームの回答 1'!$E:$E,'フォームの回答 1'!$B:$B,">="&F1,'フォームの回答 1'!$H:$H,"支出",'フォームの回答 1'!$D:$D,$A10)-SUMIFS('フォームの回答 1'!$E:$E,'フォームの回答 1'!$B:$B,">"&G1,'フォームの回答 1'!$H:$H,"支出",'フォームの回答 1'!$D:$D,$A10) -> 3652 | G10: =SUMIFS('フォームの回答 1'!$E:$E,'フォームの回答 1'!$B:$B,">="&G1,'フォームの回答 1'!$H:$H,"支出",'フォームの回答 1'!$D:$D,$A10)-SUMIFS('フォームの回答 1'!$E:$E,'フォームの回答 1'!$B:$B,">"&H1,'フォームの回答 1'!$H:$H,"支出",'フォームの回答 1'!$D:$D,$A10) -> 4070 | H10: =SUMIFS('フォームの回答 1'!$E:$E,'フォームの回答 1'!$B:$B,">="&H1,'フォームの回答 1'!$H:$H,"支出",'フォームの回答 1'!$D:$D,$A10)-SUMIFS('フォームの回答 1'!$E:$E,'フォームの回答 1'!$B:$B,">"&I1,'フォームの回答 1'!$H:$H,"支出",'フォームの回答 1'!$D:$D,$A10) -> 3388 | I10: =SUMIFS('フォームの回答 1'!$E:$E,'フォームの回答 1'!$B:$B,">="&I1,'フォームの回答 1'!$H:$H,"支出",'フォームの回答 1'!$D:$D,$A10)-SUMIFS('フォームの回答 1'!$E:$E,'フォームの回答 1'!$B:$B,">"&J1,'フォームの回答 1'!$H:$H,"支出",'フォームの回答 1'!$D:$D,$A10) -> 5522 | J10: =SUMIFS('フォームの回答 1'!$E:$E,'フォームの回答 1'!$B:$B,">="&J1,'フォームの回答 1'!$H:$H,"支出",'フォームの回答 1'!$D:$D,$A10)-SUMIFS('フォームの回答 1'!$E:$E,'フォームの回答 1'!$B:$B,">"&K1,'フォームの回答 1'!$H:$H,"支出",'フォームの回答 1'!$D:$D,$A10) -> 3388 | ... N10: =SUMIFS('フォームの回答 1'!$E:$E,'フォームの回答 1'!$B:$B,">="&N1,'フォームの回答 1'!$H:$H,"支出",'フォームの回答 1'!$D:$D,$A10)-SUMIFS('フォームの回答 1'!$E:$E,'フォームの回答 1'!$B:$B,">"&O1,'フォームの回答 1'!$H:$H,"支出",'フォームの回答 1'!$D:$D,$A10) -> 113485 | O10: =B10/12 -> 13697.083
A11: 家賃 | B11: =SUM(C11:N11) -> 2735500 | C11: =SUMIFS('フォームの回答 1'!$E:$E,'フォームの回答 1'!$B:$B,">="&C1,'フォームの回答 1'!$H:$H,"支出",'フォームの回答 1'!$D:$D,$A11)-SUMIFS('フォームの回答 1'!$E:$E,'フォームの回答 1'!$B:$B,">"&D1,'フォームの回答 1'!$H:$H,"支出",'フォームの回答 1'!$D:$D,$A11) -> 93000 | D11: =SUMIFS('フォームの回答 1'!$E:$E,'フォームの回答 1'!$B:$B,">="&D1,'フォームの回答 1'!$H:$H,"支出",'フォームの回答 1'!$D:$D,$A11)-SUMIFS('フォームの回答 1'!$E:$E,'フォームの回答 1'!$B:$B,">"&E1,'フォームの回答 1'!$H:$H,"支出",'フォームの回答 1'!$D:$D,$A11) -> 93000 | E11: =SUMIFS('フォームの回答 1'!$E:$E,'フォームの回答 1'!$B:$B,">="&E1,'フォームの回答 1'!$H:$H,"支出",'フォームの回答 1'!$D:$D,$A11)-SUMIFS('フォームの回答 1'!$E:$E,'フォームの回答 1'!$B:$B,">"&F1,'フォームの回答 1'!$H:$H,"支出",'フォームの回答 1'!$D:$D,$A11) -> 93000 | F11: =SUMIFS('フォームの回答 1'!$E:$E,'フォームの回答 1'!$B:$B,">="&F1,'フォームの回答 1'!$H:$H,"支出",'フォームの回答 1'!$D:$D,$A11)-SUMIFS('フォームの回答 1'!$E:$E,'フォームの回答 1'!$B:$B,">"&G1,'フォームの回答 1'!$H:$H,"支出",'フォームの回答 1'!$D:$D,$A11) -> 93000 | G11: =SUMIFS('フォームの回答 1'!$E:$E,'フォームの回答 1'!$B:$B,">="&G1,'フォームの回答 1'!$H:$H,"支出",'フォームの回答 1'!$D:$D,$A11)-SUMIFS('フォームの回答 1'!$E:$E,'フォームの回答 1'!$B:$B,">"&H1,'フォームの回答 1'!$H:$H,"支出",'フォームの回答 1'!$D:$D,$A11) -> 93000 | H11: =SUMIFS('フォームの回答 1'!$E:$E,'フォームの回答 1'!$B:$B,">="&H1,'フォームの回答 1'!$H:$H,"支出",'フォームの回答 1'!$D:$D,$A11)-SUMIFS('フォームの回答 1'!$E:$E,'フォームの回答 1'!$B:$B,">"&I1,'フォームの回答 1'!$H:$H,"支出",'フォームの回答 1'!$D:$D,$A11) -> 98000 | I11: =SUMIFS('フォームの回答 1'!$E:$E,'フォームの回答 1'!$B:$B,">="&I1,'フォームの回答 1'!$H:$H,"支出",'フォームの回答 1'!$D:$D,$A11)-SUMIFS('フォームの回答 1'!$E:$E,'フォームの回答 1'!$B:$B,">"&J1,'フォームの回答 1'!$H:$H,"支出",'フォームの回答 1'!$D:$D,$A11) -> 93000 | J11: =SUMIFS('フォームの回答 1'!$E:$E,'フォームの回答 1'!$B:$B,">="&J1,'フォームの回答 1'!$H:$H,"支出",'フォームの回答 1'!$D:$D,$A11)-SUMIFS('フォームの回答 1'!$E:$E,'フォームの回答 1'!$B:$B,">"&K1,'フォームの回答 1'!$H:$H,"支出",'フォームの回答 1'!$D:$D,$A11) -> 93000 | ... N11: =SUMIFS('フォームの回答 1'!$E:$E,'フォームの回答 1'!$B:$B,">="&N1,'フォームの回答 1'!$H:$H,"支出",'フォームの回答 1'!$D:$D,$A11)-SUMIFS('フォームの回答 1'!$E:$E,'フォームの回答 1'!$B:$B,">"&O1,'フォームの回答 1'!$H:$H,"支出",'フォームの回答 1'!$D:$D,$A11) -> 1707500 | O11: =B11/12 -> 227958.33
A12: 医療費 | B12: =SUM(C12:N12) -> 23671 | C12: =SUMIFS('フォームの回答 1'!$E:$E,'フォームの回答 1'!$B:$B,">="&C1,'フォームの回答 1'!$H:$H,"支出",'フォームの回答 1'!$D:$D,$A12)-SUMIFS('フォームの回答 1'!$E:$E,'フォームの回答 1'!$B:$B,">"&D1,'フォームの回答 1'!$H:$H,"支出",'フォームの回答 1'!$D:$D,$A12) -> 2136 | D12: =SUMIFS('フォームの回答 1'!$E:$E,'フォームの回答 1'!$B:$B,">="&D1,'フォームの回答 1'!$H:$H,"支出",'フォームの回答 1'!$D:$D,$A12)-SUMIFS('フォームの回答 1'!$E:$E,'フォームの回答 1'!$B:$B,">"&E1,'フォームの回答 1'!$H:$H,"支出",'フォームの回答 1'!$D:$D,$A12) -> 1405 | E12: =SUMIFS('フォームの回答 1'!$E:$E,'フォームの回答 1'!$B:$B,">="&E1,'フォームの回答 1'!$H:$H,"支出",'フォームの回答 1'!$D:$D,$A12)-SUMIFS('フォームの回答 1'!$E:$E,'フォームの回答 1'!$B:$B,">"&F1,'フォームの回答 1'!$H:$H,"支出",'フォームの回答 1'!$D:$D,$A12) -> 1889 | F12: =SUMIFS('フォームの回答 1'!$E:$E,'フォームの回答 1'!$B:$B,">="&F1,'フォームの回答 1'!$H:$H,"支出",'フォームの回答 1'!$D:$D,$A12)-SUMIFS('フォームの回答 1'!$E:$E,'フォームの回答 1'!$B:$B,">"&G1,'フォームの回答 1'!$H:$H,"支出",'フォームの回答 1'!$D:$D,$A12) -> 654 | G12: =SUMIFS('フォームの回答 1'!$E:$E,'フォームの回答 1'!$B:$B,">="&G1,'フォームの回答 1'!$H:$H,"支出",'フォームの回答 1'!$D:$D,$A12)-SUMIFS('フォームの回答 1'!$E:$E,'フォームの回答 1'!$B:$B,">"&H1,'フォームの回答 1'!$H:$H,"支出",'フォームの回答 1'!$D:$D,$A12) -> 632 | H12: =SUMIFS('フォームの回答 1'!$E:$E,'フォームの回答 1'!$B:$B,">="&H1,'フォームの回答 1'!$H:$H,"支出",'フォームの回答 1'!$D:$D,$A12)-SUMIFS('フォームの回答 1'!$E:$E,'フォームの回答 1'!$B:$B,">"&I1,'フォームの回答 1'!$H:$H,"支出",'フォームの回答 1'!$D:$D,$A12) -> 328 | I12: =SUMIFS('フォームの回答 1'!$E:$E,'フォームの回答 1'!$B:$B,">="&I1,'フォームの回答 1'!$H:$H,"支出",'フォームの回答 1'!$D:$D,$A12)-SUMIFS('フォームの回答 1'!$E:$E,'フォームの回答 1'!$B:$B,">"&J1,'フォームの回答 1'!$H:$H,"支出",'フォームの回答 1'!$D:$D,$A12) -> 0 | J12: =SUMIFS('フォームの回答 1'!$E:$E,'フォームの回答 1'!$B:$B,">="&J1,'フォームの回答 1'!$H:$H,"支出",'フォームの回答 1'!$D:$D,$A12)-SUMIFS('フォームの回答 1'!$E:$E,'フォームの回答 1'!$B:$B,">"&K1,'フォームの回答 1'!$H:$H,"支出",'フォームの回答 1'!$D:$D,$A12) -> 0 | ... N12: =SUMIFS('フォームの回答 1'!$E:$E,'フォームの回答 1'!$B:$B,">="&N1,'フォームの回答 1'!$H:$H,"支出",'フォームの回答 1'!$D:$D,$A12)-SUMIFS('フォームの回答 1'!$E:$E,'フォームの回答 1'!$B:$B,">"&O1,'フォームの回答 1'!$H:$H,"支出",'フォームの回答 1'!$D:$D,$A12) -> 13917 | O12: =B12/12 -> 1972.5833
A13: 服 | B13: =SUM(C13:N13) -> 84549 | C13: =SUMIFS('フォームの回答 1'!$E:$E,'フォームの回答 1'!$B:$B,">="&C1,'フォームの回答 1'!$H:$H,"支出",'フォームの回答 1'!$D:$D,$A13)-SUMIFS('フォームの回答 1'!$E:$E,'フォームの回答 1'!$B:$B,">"&D1,'フォームの回答 1'!$H:$H,"支出",'フォームの回答 1'!$D:$D,$A13) -> 2170 | D13: =SUMIFS('フォームの回答 1'!$E:$E,'フォームの回答 1'!$B:$B,">="&D1,'フォームの回答 1'!$H:$H,"支出",'フォームの回答 1'!$D:$D,$A13)-SUMIFS('フォームの回答 1'!$E:$E,'フォームの回答 1'!$B:$B,">"&E1,'フォームの回答 1'!$H:$H,"支出",'フォームの回答 1'!$D:$D,$A13) -> 0 | E13: =SUMIFS('フォームの回答 1'!$E:$E,'フォームの回答 1'!$B:$B,">="&E1,'フォームの回答 1'!$H:$H,"支出",'フォームの回答 1'!$D:$D,$A13)-SUMIFS('フォームの回答 1'!$E:$E,'フォームの回答 1'!$B:$B,">"&F1,'フォームの回答 1'!$H:$H,"支出",'フォームの回答 1'!$D:$D,$A13) -> 1470 | F13: =SUMIFS('フォームの回答 1'!$E:$E,'フォームの回答 1'!$B:$B,">="&F1,'フォームの回答 1'!$H:$H,"支出",'フォームの回答 1'!$D:$D,$A13)-SUMIFS('フォームの回答 1'!$E:$E,'フォームの回答 1'!$B:$B,">"&G1,'フォームの回答 1'!$H:$H,"支出",'フォームの回答 1'!$D:$D,$A13) -> 0 | G13: =SUMIFS('フォームの回答 1'!$E:$E,'フォームの回答 1'!$B:$B,">="&G1,'フォームの回答 1'!$H:$H,"支出",'フォームの回答 1'!$D:$D,$A13)-SUMIFS('フォームの回答 1'!$E:$E,'フォームの回答 1'!$B:$B,">"&H1,'フォームの回答 1'!$H:$H,"支出",'フォームの回答 1'!$D:$D,$A13) -> 0 | H13: =SUMIFS('フォームの回答 1'!$E:$E,'フォームの回答 1'!$B:$B,">="&H1,'フォームの回答 1'!$H:$H,"支出",'フォームの回答 1'!$D:$D,$A13)-SUMIFS('フォームの回答 1'!$E:$E,'フォームの回答 1'!$B:$B,">"&I1,'フォームの回答 1'!$H:$H,"支出",'フォームの回答 1'!$D:$D,$A13) -> 4509 | I13: =SUMIFS('フォームの回答 1'!$E:$E,'フォームの回答 1'!$B:$B,">="&I1,'フォームの回答 1'!$H:$H,"支出",'フォームの回答 1'!$D:$D,$A13)-SUMIFS('フォームの回答 1'!$E:$E,'フォームの回答 1'!$B:$B,">"&J1,'フォームの回答 1'!$H:$H,"支出",'フォームの回答 1'!$D:$D,$A13) -> 0 | J13: =SUMIFS('フォームの回答 1'!$E:$E,'フォームの回答 1'!$B:$B,">="&J1,'フォームの回答 1'!$H:$H,"支出",'フォームの回答 1'!$D:$D,$A13)-SUMIFS('フォームの回答 1'!$E:$E,'フォームの回答 1'!$B:$B,">"&K1,'フォームの回答 1'!$H:$H,"支出",'フォームの回答 1'!$D:$D,$A13) -> 2380 | ... N13: =SUMIFS('フォームの回答 1'!$E:$E,'フォームの回答 1'!$B:$B,">="&N1,'フォームの回答 1'!$H:$H,"支出",'フォームの回答 1'!$D:$D,$A13)-SUMIFS('フォームの回答 1'!$E:$E,'フォームの回答 1'!$B:$B,">"&O1,'フォームの回答 1'!$H:$H,"支出",'フォームの回答 1'!$D:$D,$A13) -> 46650 | O13: =B13/12 -> 7045.75
A14: 生活品 | B14: =SUM(C14:N14) -> 1004026 | C14: =SUMIFS('フォームの回答 1'!$E:$E,'フォームの回答 1'!$B:$B,">="&C1,'フォームの回答 1'!$H:$H,"支出",'フォームの回答 1'!$D:$D,$A14)-SUMIFS('フォームの回答 1'!$E:$E,'フォームの回答 1'!$B:$B,">"&D1,'フォームの回答 1'!$H:$H,"支出",'フォームの回答 1'!$D:$D,$A14) -> 13844 | D14: =SUMIFS('フォームの回答 1'!$E:$E,'フォームの回答 1'!$B:$B,">="&D1,'フォームの回答 1'!$H:$H,"支出",'フォームの回答 1'!$D:$D,$A14)-SUMIFS('フォームの回答 1'!$E:$E,'フォームの回答 1'!$B:$B,">"&E1,'フォームの回答 1'!$H:$H,"支出",'フォームの回答 1'!$D:$D,$A14) -> 20250 | E14: =SUMIFS('フォームの回答 1'!$E:$E,'フォームの回答 1'!$B:$B,">="&E1,'フォームの回答 1'!$H:$H,"支出",'フォームの回答 1'!$D:$D,$A14)-SUMIFS('フォームの回答 1'!$E:$E,'フォームの回答 1'!$B:$B,">"&F1,'フォームの回答 1'!$H:$H,"支出",'フォームの回答 1'!$D:$D,$A14) -> 40818 | F14: =SUMIFS('フォームの回答 1'!$E:$E,'フォームの回答 1'!$B:$B,">="&F1,'フォームの回答 1'!$H:$H,"支出",'フォームの回答 1'!$D:$D,$A14)-SUMIFS('フォームの回答 1'!$E:$E,'フォームの回答 1'!$B:$B,">"&G1,'フォームの回答 1'!$H:$H,"支出",'フォームの回答 1'!$D:$D,$A14) -> 48967 | G14: =SUMIFS('フォームの回答 1'!$E:$E,'フォームの回答 1'!$B:$B,">="&G1,'フォームの回答 1'!$H:$H,"支出",'フォームの回答 1'!$D:$D,$A14)-SUMIFS('フォームの回答 1'!$E:$E,'フォームの回答 1'!$B:$B,">"&H1,'フォームの回答 1'!$H:$H,"支出",'フォームの回答 1'!$D:$D,$A14) -> 77772 | H14: =SUMIFS('フォームの回答 1'!$E:$E,'フォームの回答 1'!$B:$B,">="&H1,'フォームの回答 1'!$H:$H,"支出",'フォームの回答 1'!$D:$D,$A14)-SUMIFS('フォームの回答 1'!$E:$E,'フォームの回答 1'!$B:$B,">"&I1,'フォームの回答 1'!$H:$H,"支出",'フォームの回答 1'!$D:$D,$A14) -> 33718 | I14: =SUMIFS('フォームの回答 1'!$E:$E,'フォームの回答 1'!$B:$B,">="&I1,'フォームの回答 1'!$H:$H,"支出",'フォームの回答 1'!$D:$D,$A14)-SUMIFS('フォームの回答 1'!$E:$E,'フォームの回答 1'!$B:$B,">"&J1,'フォームの回答 1'!$H:$H,"支出",'フォームの回答 1'!$D:$D,$A14) -> 23893 | J14: =SUMIFS('フォームの回答 1'!$E:$E,'フォームの回答 1'!$B:$B,">="&J1,'フォームの回答 1'!$H:$H,"支出",'フォームの回答 1'!$D:$D,$A14)-SUMIFS('フォームの回答 1'!$E:$E,'フォームの回答 1'!$B:$B,">"&K1,'フォームの回答 1'!$H:$H,"支出",'フォームの回答 1'!$D:$D,$A14) -> 31742 | ... N14: =SUMIFS('フォームの回答 1'!$E:$E,'フォームの回答 1'!$B:$B,">="&N1,'フォームの回答 1'!$H:$H,"支出",'フォームの回答 1'!$D:$D,$A14)-SUMIFS('フォームの回答 1'!$E:$E,'フォームの回答 1'!$B:$B,">"&O1,'フォームの回答 1'!$H:$H,"支出",'フォームの回答 1'!$D:$D,$A14) -> 626256 | O14: =B14/12 -> 83668.833
A15: 書籍代 | B15: =SUM(C15:N15) -> 200722 | C15: =SUMIFS('フォームの回答 1'!$E:$E,'フォームの回答 1'!$B:$B,">="&C1,'フォームの回答 1'!$H:$H,"支出",'フォームの回答 1'!$D:$D,$A15)-SUMIFS('フォームの回答 1'!$E:$E,'フォームの回答 1'!$B:$B,">"&D1,'フォームの回答 1'!$H:$H,"支出",'フォームの回答 1'!$D:$D,$A15) -> 12320 | D15: =SUMIFS('フォームの回答 1'!$E:$E,'フォームの回答 1'!$B:$B,">="&D1,'フォームの回答 1'!$H:$H,"支出",'フォームの回答 1'!$D:$D,$A15)-SUMIFS('フォームの回答 1'!$E:$E,'フォームの回答 1'!$B:$B,">"&E1,'フォームの回答 1'!$H:$H,"支出",'フォームの回答 1'!$D:$D,$A15) -> 7375 | E15: =SUMIFS('フォームの回答 1'!$E:$E,'フォームの回答 1'!$B:$B,">="&E1,'フォームの回答 1'!$H:$H,"支出",'フォームの回答 1'!$D:$D,$A15)-SUMIFS('フォームの回答 1'!$E:$E,'フォームの回答 1'!$B:$B,">"&F1,'フォームの回答 1'!$H:$H,"支出",'フォームの回答 1'!$D:$D,$A15) -> 8238 | F15: =SUMIFS('フォームの回答 1'!$E:$E,'フォームの回答 1'!$B:$B,">="&F1,'フォームの回答 1'!$H:$H,"支出",'フォームの回答 1'!$D:$D,$A15)-SUMIFS('フォームの回答 1'!$E:$E,'フォームの回答 1'!$B:$B,">"&G1,'フォームの回答 1'!$H:$H,"支出",'フォームの回答 1'!$D:$D,$A15) -> 10010 | G15: =SUMIFS('フォームの回答 1'!$E:$E,'フォームの回答 1'!$B:$B,">="&G1,'フォームの回答 1'!$H:$H,"支出",'フォームの回答 1'!$D:$D,$A15)-SUMIFS('フォームの回答 1'!$E:$E,'フォームの回答 1'!$B:$B,">"&H1,'フォームの回答 1'!$H:$H,"支出",'フォームの回答 1'!$D:$D,$A15) -> 14599 | H15: =SUMIFS('フォームの回答 1'!$E:$E,'フォームの回答 1'!$B:$B,">="&H1,'フォームの回答 1'!$H:$H,"支出",'フォームの回答 1'!$D:$D,$A15)-SUMIFS('フォームの回答 1'!$E:$E,'フォームの回答 1'!$B:$B,">"&I1,'フォームの回答 1'!$H:$H,"支出",'フォームの回答 1'!$D:$D,$A15) -> 902 | I15: =SUMIFS('フォームの回答 1'!$E:$E,'フォームの回答 1'!$B:$B,">="&I1,'フォームの回答 1'!$H:$H,"支出",'フォームの回答 1'!$D:$D,$A15)-SUMIFS('フォームの回答 1'!$E:$E,'フォームの回答 1'!$B:$B,">"&J1,'フォームの回答 1'!$H:$H,"支出",'フォームの回答 1'!$D:$D,$A15) -> 11099 | J15: =SUMIFS('フォームの回答 1'!$E:$E,'フォームの回答 1'!$B:$B,">="&J1,'フォームの回答 1'!$H:$H,"支出",'フォームの回答 1'!$D:$D,$A15)-SUMIFS('フォームの回答 1'!$E:$E,'フォームの回答 1'!$B:$B,">"&K1,'フォームの回答 1'!$H:$H,"支出",'フォームの回答 1'!$D:$D,$A15) -> 2400 | ... N15: =SUMIFS('フォームの回答 1'!$E:$E,'フォームの回答 1'!$B:$B,">="&N1,'フォームの回答 1'!$H:$H,"支出",'フォームの回答 1'!$D:$D,$A15)-SUMIFS('フォームの回答 1'!$E:$E,'フォームの回答 1'!$B:$B,">"&O1,'フォームの回答 1'!$H:$H,"支出",'フォームの回答 1'!$D:$D,$A15) -> 115837 | O15: =B15/12 -> 16726.833
A16: 奨学金・ローン返済 | B16: =SUM(C16:N16) -> 2132289 | C16: =SUMIFS('フォームの回答 1'!$E:$E,'フォームの回答 1'!$B:$B,">="&C1,'フォームの回答 1'!$H:$H,"支出",'フォームの回答 1'!$D:$D,$A16)-SUMIFS('フォームの回答 1'!$E:$E,'フォームの回答 1'!$B:$B,">"&D1,'フォームの回答 1'!$H:$H,"支出",'フォームの回答 1'!$D:$D,$A16) -> 148589 | D16: =SUMIFS('フォームの回答 1'!$E:$E,'フォームの回答 1'!$B:$B,">="&D1,'フォームの回答 1'!$H:$H,"支出",'フォームの回答 1'!$D:$D,$A16)-SUMIFS('フォームの回答 1'!$E:$E,'フォームの回答 1'!$B:$B,">"&E1,'フォームの回答 1'!$H:$H,"支出",'フォームの回答 1'!$D:$D,$A16) -> 67000 | E16: =SUMIFS('フォームの回答 1'!$E:$E,'フォームの回答 1'!$B:$B,">="&E1,'フォームの回答 1'!$H:$H,"支出",'フォームの回答 1'!$D:$D,$A16)-SUMIFS('フォームの回答 1'!$E:$E,'フォームの回答 1'!$B:$B,">"&F1,'フォームの回答 1'!$H:$H,"支出",'フォームの回答 1'!$D:$D,$A16) -> 67000 | F16: =SUMIFS('フォームの回答 1'!$E:$E,'フォームの回答 1'!$B:$B,">="&F1,'フォームの回答 1'!$H:$H,"支出",'フォームの回答 1'!$D:$D,$A16)-SUMIFS('フォームの回答 1'!$E:$E,'フォームの回答 1'!$B:$B,">"&G1,'フォームの回答 1'!$H:$H,"支出",'フォームの回答 1'!$D:$D,$A16) -> 67000 | G16: =SUMIFS('フォームの回答 1'!$E:$E,'フォームの回答 1'!$B:$B,">="&G1,'フォームの回答 1'!$H:$H,"支出",'フォームの回答 1'!$D:$D,$A16)-SUMIFS('フォームの回答 1'!$E:$E,'フォームの回答 1'!$B:$B,">"&H1,'フォームの回答 1'!$H:$H,"支出",'フォームの回答 1'!$D:$D,$A16) -> 67000 | H16: =SUMIFS('フォームの回答 1'!$E:$E,'フォームの回答 1'!$B:$B,">="&H1,'フォームの回答 1'!$H:$H,"支出",'フォームの回答 1'!$D:$D,$A16)-SUMIFS('フォームの回答 1'!$E:$E,'フォームの回答 1'!$B:$B,">"&I1,'フォームの回答 1'!$H:$H,"支出",'フォームの回答 1'!$D:$D,$A16) -> 67000 | I16: =SUMIFS('フォームの回答 1'!$E:$E,'フォームの回答 1'!$B:$B,">="&I1,'フォームの回答 1'!$H:$H,"支出",'フォームの回答 1'!$D:$D,$A16)-SUMIFS('フォームの回答 1'!$E:$E,'フォームの回答 1'!$B:$B,">"&J1,'フォームの回答 1'!$H:$H,"支出",'フォームの回答 1'!$D:$D,$A16) -> 68500 | J16: =SUMIFS('フォームの回答 1'!$E:$E,'フォームの回答 1'!$B:$B,">="&J1,'フォームの回答 1'!$H:$H,"支出",'フォームの回答 1'!$D:$D,$A16)-SUMIFS('フォームの回答 1'!$E:$E,'フォームの回答 1'!$B:$B,">"&K1,'フォームの回答 1'!$H:$H,"支出",'フォームの回答 1'!$D:$D,$A16) -> 67000 | ... N16: =SUMIFS('フォームの回答 1'!$E:$E,'フォームの回答 1'!$B:$B,">="&N1,'フォームの回答 1'!$H:$H,"支出",'フォームの回答 1'!$D:$D,$A16)-SUMIFS('フォームの回答 1'!$E:$E,'フォームの回答 1'!$B:$B,">"&O1,'フォームの回答 1'!$H:$H,"支出",'フォームの回答 1'!$D:$D,$A16) -> 1312200 | O16: =B16/12 -> 177690.75
A17: ツール | B17: =SUM(C17:N17) -> 160747 | C17: =SUMIFS('フォームの回答 1'!$E:$E,'フォームの回答 1'!$B:$B,">="&C1,'フォームの回答 1'!$H:$H,"支出",'フォームの回答 1'!$D:$D,$A17)-SUMIFS('フォームの回答 1'!$E:$E,'フォームの回答 1'!$B:$B,">"&D1,'フォームの回答 1'!$H:$H,"支出",'フォームの回答 1'!$D:$D,$A17) -> 2060 | D17: =SUMIFS('フォームの回答 1'!$E:$E,'フォームの回答 1'!$B:$B,">="&D1,'フォームの回答 1'!$H:$H,"支出",'フォームの回答 1'!$D:$D,$A17)-SUMIFS('フォームの回答 1'!$E:$E,'フォームの回答 1'!$B:$B,">"&E1,'フォームの回答 1'!$H:$H,"支出",'フォームの回答 1'!$D:$D,$A17) -> 880 | E17: =SUMIFS('フォームの回答 1'!$E:$E,'フォームの回答 1'!$B:$B,">="&E1,'フォームの回答 1'!$H:$H,"支出",'フォームの回答 1'!$D:$D,$A17)-SUMIFS('フォームの回答 1'!$E:$E,'フォームの回答 1'!$B:$B,">"&F1,'フォームの回答 1'!$H:$H,"支出",'フォームの回答 1'!$D:$D,$A17) -> 2060 | F17: =SUMIFS('フォームの回答 1'!$E:$E,'フォームの回答 1'!$B:$B,">="&F1,'フォームの回答 1'!$H:$H,"支出",'フォームの回答 1'!$D:$D,$A17)-SUMIFS('フォームの回答 1'!$E:$E,'フォームの回答 1'!$B:$B,">"&G1,'フォームの回答 1'!$H:$H,"支出",'フォームの回答 1'!$D:$D,$A17) -> 2060 | G17: =SUMIFS('フォームの回答 1'!$E:$E,'フォームの回答 1'!$B:$B,">="&G1,'フォームの回答 1'!$H:$H,"支出",'フォームの回答 1'!$D:$D,$A17)-SUMIFS('フォームの回答 1'!$E:$E,'フォームの回答 1'!$B:$B,">"&H1,'フォームの回答 1'!$H:$H,"支出",'フォームの回答 1'!$D:$D,$A17) -> 4076 | H17: =SUMIFS('フォームの回答 1'!$E:$E,'フォームの回答 1'!$B:$B,">="&H1,'フォームの回答 1'!$H:$H,"支出",'フォームの回答 1'!$D:$D,$A17)-SUMIFS('フォームの回答 1'!$E:$E,'フォームの回答 1'!$B:$B,">"&I1,'フォームの回答 1'!$H:$H,"支出",'フォームの回答 1'!$D:$D,$A17) -> 4097 | I17: =SUMIFS('フォームの回答 1'!$E:$E,'フォームの回答 1'!$B:$B,">="&I1,'フォームの回答 1'!$H:$H,"支出",'フォームの回答 1'!$D:$D,$A17)-SUMIFS('フォームの回答 1'!$E:$E,'フォームの回答 1'!$B:$B,">"&J1,'フォームの回答 1'!$H:$H,"支出",'フォームの回答 1'!$D:$D,$A17) -> 4269 | J17: =SUMIFS('フォームの回答 1'!$E:$E,'フォームの回答 1'!$B:$B,">="&J1,'フォームの回答 1'!$H:$H,"支出",'フォームの回答 1'!$D:$D,$A17)-SUMIFS('フォームの回答 1'!$E:$E,'フォームの回答 1'!$B:$B,">"&K1,'フォームの回答 1'!$H:$H,"支出",'フォームの回答 1'!$D:$D,$A17) -> 3905 | ... N17: =SUMIFS('フォームの回答 1'!$E:$E,'フォームの回答 1'!$B:$B,">="&N1,'フォームの回答 1'!$H:$H,"支出",'フォームの回答 1'!$D:$D,$A17)-SUMIFS('フォームの回答 1'!$E:$E,'フォームの回答 1'!$B:$B,">"&O1,'フォームの回答 1'!$H:$H,"支出",'フォームの回答 1'!$D:$D,$A17) -> 112577 | O17: =B17/12 -> 13395.583
A18: 勉強費 | B18: =SUM(C18:N18) -> 226758 | C18: =SUMIFS('フォームの回答 1'!$E:$E,'フォームの回答 1'!$B:$B,">="&C1,'フォームの回答 1'!$H:$H,"支出",'フォームの回答 1'!$D:$D,$A18)-SUMIFS('フォームの回答 1'!$E:$E,'フォームの回答 1'!$B:$B,">"&D1,'フォームの回答 1'!$H:$H,"支出",'フォームの回答 1'!$D:$D,$A18) -> 7480 | D18: =SUMIFS('フォームの回答 1'!$E:$E,'フォームの回答 1'!$B:$B,">="&D1,'フォームの回答 1'!$H:$H,"支出",'フォームの回答 1'!$D:$D,$A18)-SUMIFS('フォームの回答 1'!$E:$E,'フォームの回答 1'!$B:$B,">"&E1,'フォームの回答 1'!$H:$H,"支出",'フォームの回答 1'!$D:$D,$A18) -> 7480 | E18: =SUMIFS('フォームの回答 1'!$E:$E,'フォームの回答 1'!$B:$B,">="&E1,'フォームの回答 1'!$H:$H,"支出",'フォームの回答 1'!$D:$D,$A18)-SUMIFS('フォームの回答 1'!$E:$E,'フォームの回答 1'!$B:$B,">"&F1,'フォームの回答 1'!$H:$H,"支出",'フォームの回答 1'!$D:$D,$A18) -> 7480 | F18: =SUMIFS('フォームの回答 1'!$E:$E,'フォームの回答 1'!$B:$B,">="&F1,'フォームの回答 1'!$H:$H,"支出",'フォームの回答 1'!$D:$D,$A18)-SUMIFS('フォームの回答 1'!$E:$E,'フォームの回答 1'!$B:$B,">"&G1,'フォームの回答 1'!$H:$H,"支出",'フォームの回答 1'!$D:$D,$A18) -> 8880 | G18: =SUMIFS('フォームの回答 1'!$E:$E,'フォームの回答 1'!$B:$B,">="&G1,'フォームの回答 1'!$H:$H,"支出",'フォームの回答 1'!$D:$D,$A18)-SUMIFS('フォームの回答 1'!$E:$E,'フォームの回答 1'!$B:$B,">"&H1,'フォームの回答 1'!$H:$H,"支出",'フォームの回答 1'!$D:$D,$A18) -> 11420 | H18: =SUMIFS('フォームの回答 1'!$E:$E,'フォームの回答 1'!$B:$B,">="&H1,'フォームの回答 1'!$H:$H,"支出",'フォームの回答 1'!$D:$D,$A18)-SUMIFS('フォームの回答 1'!$E:$E,'フォームの回答 1'!$B:$B,">"&I1,'フォームの回答 1'!$H:$H,"支出",'フォームの回答 1'!$D:$D,$A18) -> 7480 | I18: =SUMIFS('フォームの回答 1'!$E:$E,'フォームの回答 1'!$B:$B,">="&I1,'フォームの回答 1'!$H:$H,"支出",'フォームの回答 1'!$D:$D,$A18)-SUMIFS('フォームの回答 1'!$E:$E,'フォームの回答 1'!$B:$B,">"&J1,'フォームの回答 1'!$H:$H,"支出",'フォームの回答 1'!$D:$D,$A18) -> 7480 | J18: =SUMIFS('フォームの回答 1'!$E:$E,'フォームの回答 1'!$B:$B,">="&J1,'フォームの回答 1'!$H:$H,"支出",'フォームの回答 1'!$D:$D,$A18)-SUMIFS('フォームの回答 1'!$E:$E,'フォームの回答 1'!$B:$B,">"&K1,'フォームの回答 1'!$H:$H,"支出",'フォームの回答 1'!$D:$D,$A18) -> 8880 | ... N18: =SUMIFS('フォームの回答 1'!$E:$E,'フォームの回答 1'!$B:$B,">="&N1,'フォームの回答 1'!$H:$H,"支出",'フォームの回答 1'!$D:$D,$A18)-SUMIFS('フォームの回答 1'!$E:$E,'フォームの回答 1'!$B:$B,">"&O1,'フォームの回答 1'!$H:$H,"支出",'フォームの回答 1'!$D:$D,$A18) -> 127738 | O18: =B18/12 -> 18896.5

Sheet 【Monthly】2025年
B1: 合計金額 | C1: 45658 | D1: 45689 | E1: 45717 | F1: 45748 | G1: 45778 | H1: 45809 | I1: 45839 | J1: 45870 | K1: 45901 | L1: 45931 | M1: 45962 | N1: 45992
A2: 収入 | B2: =SUM(C2:H2) -> 2435991 | C2: =SUMIFS('フォームの回答 1'!$E:$E,'フォームの回答 1'!$B:$B,">="&C1,'フォームの回答 1'!$H:$H,"収入")-SUMIFS('フォームの回答 1'!$E:$E,'フォームの回答 1'!$B:$B,">"&D1,'フォームの回答 1'!$H:$H,"収入") -> 386393 | D2: =SUMIFS('フォームの回答 1'!$E:$E,'フォームの回答 1'!$B:$B,">="&D1,'フォームの回答 1'!$H:$H,"収入")-SUMIFS('フォームの回答 1'!$E:$E,'フォームの回答 1'!$B:$B,">"&E1,'フォームの回答 1'!$H:$H,"収入") -> 413503 | E2: =SUMIFS('フォームの回答 1'!$E:$E,'フォームの回答 1'!$B:$B,">="&E1,'フォームの回答 1'!$H:$H,"収入")-SUMIFS('フォームの回答 1'!$E:$E,'フォームの回答 1'!$B:$B,">"&F1,'フォームの回答 1'!$H:$H,"収入") -> 427908 | F2: =SUMIFS('フォームの回答 1'!$E:$E,'フォームの回答 1'!$B:$B,">="&F1,'フォームの回答 1'!$H:$H,"収入")-SUMIFS('フォームの回答 1'!$E:$E,'フォームの回答 1'!$B:$B,">"&G1,'フォームの回答 1'!$H:$H,"収入") -> 426469 | G2: =SUMIFS('フォームの回答 1'!$E:$E,'フォームの回答 1'!$B:$B,">="&G1,'フォームの回答 1'!$H:$H,"収入")-SUMIFS('フォームの回答 1'!$E:$E,'フォームの回答 1'!$B:$B,">"&H1,'フォームの回答 1'!$H:$H,"収入") -> 395695 | H2: =SUMIFS('フォームの回答 1'!$E:$E,'フォームの回答 1'!$B:$B,">="&H1,'フォームの回答 1'!$H:$H,"収入")-SUMIFS('フォームの回答 1'!$E:$E,'フォームの回答 1'!$B:$B,">"&I1,'フォームの回答 1'!$H:$H,"収入") -> 386023 | I2: =SUMIFS('フォームの回答 1'!$E:$E,'フォームの回答 1'!$B:$B,">="&I1,'フォームの回答 1'!$H:$H,"収入")-SUMIFS('フォームの回答 1'!$E:$E,'フォームの回答 1'!$B:$B,">"&J1,'フォームの回答 1'!$H:$H,"収入") -> 525773 | J2: =SUMIFS('フォームの回答 1'!$E:$E,'フォームの回答 1'!$B:$B,">="&J1,'フォームの回答 1'!$H:$H,"収入")-SUMIFS('フォームの回答 1'!$E:$E,'フォームの回答 1'!$B:$B,">"&K1,'フォームの回答 1'!$H:$H,"収入") -> 403616 | ... N2: =SUMIFS('フォームの回答 1'!$E:$E,'フォームの回答 1'!$B:$B,">="&N1,'フォームの回答 1'!$H:$H,"収入")-SUMIFS('フォームの回答 1'!$E:$E,'フォームの回答 1'!$B:$B,">"&O1,'フォームの回答 1'!$H:$H,"収入") -> 2174466
A3: 支出 | B3: =SUM(C3:H3) -> 2706670 | C3: =SUMIFS('フォームの回答 1'!$E:$E,'フォームの回答 1'!$B:$B,">="&C1,'フォームの回答 1'!$H:$H,"支出")-SUMIFS('フォームの回答 1'!$E:$E,'フォームの回答 1'!$B:$B,">"&D1,'フォームの回答 1'!$H:$H,"支出") -> 425964 | D3: =SUMIFS('フォームの回答 1'!$E:$E,'フォームの回答 1'!$B:$B,">="&D1,'フォームの回答 1'!$H:$H,"支出")-SUMIFS('フォームの回答 1'!$E:$E,'フォームの回答 1'!$B:$B,">"&E1,'フォームの回答 1'!$H:$H,"支出") -> 396721 | E3: =SUMIFS('フォームの回答 1'!$E:$E,'フォームの回答 1'!$B:$B,">="&E1,'フォームの回答 1'!$H:$H,"支出")-SUMIFS('フォームの回答 1'!$E:$E,'フォームの回答 1'!$B:$B,">"&F1,'フォームの回答 1'!$H:$H,"支出") -> 375567 | F3: =SUMIFS('フォームの回答 1'!$E:$E,'フォームの回答 1'!$B:$B,">="&F1,'フォームの回答 1'!$H:$H,"支出")-SUMIFS('フォームの回答 1'!$E:$E,'フォームの回答 1'!$B:$B,">"&G1,'フォームの回答 1'!$H:$H,"支出") -> 423153 | G3: =SUMIFS('フォームの回答 1'!$E:$E,'フォームの回答 1'!$B:$B,">="&G1,'フォームの回答 1'!$H:$H,"支出")-SUMIFS('フォームの回答 1'!$E:$E,'フォームの回答 1'!$B:$B,">"&H1,'フォームの回答 1'!$H:$H,"支出") -> 572535 | H3: =SUMIFS('フォームの回答 1'!$E:$E,'フォームの回答 1'!$B:$B,">="&H1,'フォームの回答 1'!$H:$H,"支出")-SUMIFS('フォームの回答 1'!$E:$E,'フォームの回答 1'!$B:$B,">"&I1,'フォームの回答 1'!$H:$H,"支出") -> 512730 | I3: =SUMIFS('フォームの回答 1'!$E:$E,'フォームの回答 1'!$B:$B,">="&I1,'フォームの回答 1'!$H:$H,"支出")-SUMIFS('フォームの回答 1'!$E:$E,'フォームの回答 1'!$B:$B,">"&J1,'フォームの回答 1'!$H:$H,"支出") -> 440281 | J3: =SUMIFS('フォームの回答 1'!$E:$E,'フォームの回答 1'!$B:$B,">="&J1,'フォームの回答 1'!$H:$H,"支出")-SUMIFS('フォームの回答 1'!$E:$E,'フォームの回答 1'!$B:$B,">"&K1,'フォームの回答 1'!$H:$H,"支出") -> 432558 | ... N3: =SUMIFS('フォームの回答 1'!$E:$E,'フォームの回答 1'!$B:$B,">="&N1,'フォームの回答 1'!$H:$H,"支出")-SUMIFS('フォームの回答 1'!$E:$E,'フォームの回答 1'!$B:$B,">"&O1,'フォームの回答 1'!$H:$H,"支出") -> 2304517
A4: 差額 | B4: =SUM(C4:H4) -> -270679 | C4: =C2-C3 -> -39571 | D4: =D2-D3 -> 16782 | E4: =E2-E3 -> 52341 | F4: =F2-F3 -> 3316 | G4: =G2-G3 -> -176840 | H4: =H2-H3 -> -126707 | I4: =I2-I3 -> 85492 | J4: =J2-J3 -> -28942 | ... N4: =N2-N3 -> -130051
B5: 内訳
A6: 食費 | B6: =SUM(C6:I6) -> 283870 | C6: =SUMIFS('フォームの回答 1'!$E:$E,'フォームの回答 1'!$B:$B,">="&C1,'フォームの回答 1'!$H:$H,"支出",'フォームの回答 1'!$D:$D,$A6)-SUMIFS('フォームの回答 1'!$E:$E,'フォームの回答 1'!$B:$B,">"&D1,'フォームの回答 1'!$H:$H,"支出",'フォームの回答 1'!$D:$D,$A6) -> 41207 | D6: =SUMIFS('フォームの回答 1'!$E:$E,'フォームの回答 1'!$B:$B,">="&D1,'フォームの回答 1'!$H:$H,"支出",'フォームの回答 1'!$D:$D,$A6)-SUMIFS('フォームの回答 1'!$E:$E,'フォームの回答 1'!$B:$B,">"&E1,'フォームの回答 1'!$H:$H,"支出",'フォームの回答 1'!$D:$D,$A6) -> 28100 | E6: =SUMIFS('フォームの回答 1'!$E:$E,'フォームの回答 1'!$B:$B,">="&E1,'フォームの回答 1'!$H:$H,"支出",'フォームの回答 1'!$D:$D,$A6)-SUMIFS('フォームの回答 1'!$E:$E,'フォームの回答 1'!$B:$B,">"&F1,'フォームの回答 1'!$H:$H,"支出",'フォームの回答 1'!$D:$D,$A6) -> 39863 | F6: =SUMIFS('フォームの回答 1'!$E:$E,'フォームの回答 1'!$B:$B,">="&F1,'フォームの回答 1'!$H:$H,"支出",'フォームの回答 1'!$D:$D,$A6)-SUMIFS('フォームの回答 1'!$E:$E,'フォームの回答 1'!$B:$B,">"&G1,'フォームの回答 1'!$H:$H,"支出",'フォームの回答 1'!$D:$D,$A6) -> 36592 | G6: =SUMIFS('フォームの回答 1'!$E:$E,'フォームの回答 1'!$B:$B,">="&G1,'フォームの回答 1'!$H:$H,"支出",'フォームの回答 1'!$D:$D,$A6)-SUMIFS('フォームの回答 1'!$E:$E,'フォームの回答 1'!$B:$B,">"&H1,'フォームの回答 1'!$H:$H,"支出",'フォームの回答 1'!$D:$D,$A6) -> 44509 | H6: =SUMIFS('フォームの回答 1'!$E:$E,'フォームの回答 1'!$B:$B,">="&H1,'フォームの回答 1'!$H:$H,"支出",'フォームの回答 1'!$D:$D,$A6)-SUMIFS('フォームの回答 1'!$E:$E,'フォームの回答 1'!$B:$B,">"&I1,'フォームの回答 1'!$H:$H,"支出",'フォームの回答 1'!$D:$D,$A6) -> 43062 | I6: =SUMIFS('フォームの回答 1'!$E:$E,'フォームの回答 1'!$B:$B,">="&I1,'フォームの回答 1'!$H:$H,"支出",'フォームの回答 1'!$D:$D,$A6)-SUMIFS('フォームの回答 1'!$E:$E,'フォームの回答 1'!$B:$B,">"&J1,'フォームの回答 1'!$H:$H,"支出",'フォームの回答 1'!$D:$D,$A6) -> 50537 | J6: =SUMIFS('フォームの回答 1'!$E:$E,'フォームの回答 1'!$B:$B,">="&J1,'フォームの回答 1'!$H:$H,"支出",'フォームの回答 1'!$D:$D,$A6)-SUMIFS('フォームの回答 1'!$E:$E,'フォームの回答 1'!$B:$B,">"&K1,'フォームの回答 1'!$H:$H,"支出",'フォームの回答 1'!$D:$D,$A6) -> 49659 | ... N6: =SUMIFS('フォームの回答 1'!$E:$E,'フォームの回答 1'!$B:$B,">="&N1,'フォームの回答 1'!$H:$H,"支出",'フォームの回答 1'!$D:$D,$A6)-SUMIFS('フォームの回答 1'!$E:$E,'フォームの回答 1'!$B:$B,">"&O1,'フォームの回答 1'!$H:$H,"支出",'フォームの回答 1'!$D:$D,$A6) -> 156324
A7: 接待交際費 | B7: =SUM(C7:I7) -> 491254 | C7: =SUMIFS('フォームの回答 1'!$E:$E,'フォームの回答 1'!$B:$B,">="&C1,'フォームの回答 1'!$H:$H,"支出",'フォームの回答 1'!$D:$D,$A7)-SUMIFS('フォームの回答 1'!$E:$E,'フォームの回答 1'!$B:$B,">"&D1,'フォームの回答 1'!$H:$H,"支出",'フォームの回答 1'!$D:$D,$A7) -> 35920 | D7: =SUMIFS('フォームの回答 1'!$E:$E,'フォームの回答 1'!$B:$B,">="&D1,'フォームの回答 1'!$H:$H,"支出",'フォームの回答 1'!$D:$D,$A7)-SUMIFS('フォームの回答 1'!$E:$E,'フォームの回答 1'!$B:$B,">"&E1,'フォームの回答 1'!$H:$H,"支出",'フォームの回答 1'!$D:$D,$A7) -> 81496 | E7: =SUMIFS('フォームの回答 1'!$E:$E,'フォームの回答 1'!$B:$B,">="&E1,'フォームの回答 1'!$H:$H,"支出",'フォームの回答 1'!$D:$D,$A7)-SUMIFS('フォームの回答 1'!$E:$E,'フォームの回答 1'!$B:$B,">"&F1,'フォームの回答 1'!$H:$H,"支出",'フォームの回答 1'!$D:$D,$A7) -> 35321 | F7: =SUMIFS('フォームの回答 1'!$E:$E,'フォームの回答 1'!$B:$B,">="&F1,'フォームの回答 1'!$H:$H,"支出",'フォームの回答 1'!$D:$D,$A7)-SUMIFS('フォームの回答 1'!$E:$E,'フォームの回答 1'!$B:$B,">"&G1,'フォームの回答 1'!$H:$H,"支出",'フォームの回答 1'!$D:$D,$A7) -> 83624 | G7: =SUMIFS('フォームの回答 1'!$E:$E,'フォームの回答 1'!$B:$B,">="&G1,'フォームの回答 1'!$H:$H,"支出",'フォームの回答 1'!$D:$D,$A7)-SUMIFS('フォームの回答 1'!$E:$E,'フォームの回答 1'!$B:$B,">"&H1,'フォームの回答 1'!$H:$H,"支出",'フォームの回答 1'!$D:$D,$A7) -> 71718 | H7: =SUMIFS('フォームの回答 1'!$E:$E,'フォームの回答 1'!$B:$B,">="&H1,'フォームの回答 1'!$H:$H,"支出",'フォームの回答 1'!$D:$D,$A7)-SUMIFS('フォームの回答 1'!$E:$E,'フォームの回答 1'!$B:$B,">"&I1,'フォームの回答 1'!$H:$H,"支出",'フォームの回答 1'!$D:$D,$A7) -> 140899 | I7: =SUMIFS('フォームの回答 1'!$E:$E,'フォームの回答 1'!$B:$B,">="&I1,'フォームの回答 1'!$H:$H,"支出",'フォームの回答 1'!$D:$D,$A7)-SUMIFS('フォームの回答 1'!$E:$E,'フォームの回答 1'!$B:$B,">"&J1,'フォームの回答 1'!$H:$H,"支出",'フォームの回答 1'!$D:$D,$A7) -> 42276 | J7: =SUMIFS('フォームの回答 1'!$E:$E,'フォームの回答 1'!$B:$B,">="&J1,'フォームの回答 1'!$H:$H,"支出",'フォームの回答 1'!$D:$D,$A7)-SUMIFS('フォームの回答 1'!$E:$E,'フォームの回答 1'!$B:$B,">"&K1,'フォームの回答 1'!$H:$H,"支出",'フォームの回答 1'!$D:$D,$A7) -> 76542 | ... N7: =SUMIFS('フォームの回答 1'!$E:$E,'フォームの回答 1'!$B:$B,">="&N1,'フォームの回答 1'!$H:$H,"支出",'フォームの回答 1'!$D:$D,$A7)-SUMIFS('フォームの回答 1'!$E:$E,'フォームの回答 1'!$B:$B,">"&O1,'フォームの回答 1'!$H:$H,"支出",'フォームの回答 1'!$D:$D,$A7) -> 366572
